Workbook

Sheet 表格说明
A1: 表格说明

Sheet DSP内部数据
B1: VariateName | C1: DateType | D1: EnumTab | E1: DisplayDigit | F1: DataType Length | G1: ArrayCnt | H1: Total Length | I1: DefaultValue | J1: MaxValue | K1: MinValue | L1: Unit | M1: RW | N1: RAM | O1: FLASH | P1: EEPROM | Q1: Calibration | R1: STRUCT | S1: 数据来自CPU | T1: 精度 | U1: 数据类型 | V1: 数据上传 等级 | W1: 数据分类 | X1: UPP 模型号 | Y1: 备注
A2: 固件版本号版本 | B2: ParamProductType | C2: Sys_U16 | E2: 0 | F2: 2 | G2: 15 | H2: 30 | I2: 0 | J2: 65534 | K2: 0 | M2: RO | N2: N | O2: Y | P2: N | Q2: Y | R2: PARAM_MONITOR_DATA_STR | S2: CPU2 | T2: {=_xlfn.FILTER(POWER(0.1,$E$2:$E$5009),$A$2:$A$5009<>"")} -> 1 | U2: {=_xlfn.FILTER(IF($G$2:$G$5009<>1,"STRING",IF(SUBSTITUTE($C$2:$C$5009,"Sys_","")="F32","S32",SUBSTITUTE($C$2:$C$5009,"Sys_",""))),$V$2:$V$5009<>"")} -> STRING | V2: 2：UPM进行轮询 | W2: 系统参数1 | X2: {=_xlfn.FILTER((W$2:W$5009="系统参数1")*1+(W$2:W$5009="系统参数2")*2+(W$2:W$5009="任务级观测量")*99+(W$2:W$5009="中断级观测量")*100+(W$2:W$5009="控制参数设置")*102+(W$2:W$5009="任务级标定量")*103,W$2:W$5009<>"")} -> 1
A3: 机器型号 | B3: ParamProductCode | C3: Sys_U16 | E3: 0 | F3: 2 | G3: 8 | H3: 16 | I3: 0 | J3: 65535 | K3: 0 | M3: RO | N3: N | O3: Y | P3: N | Q3: Y | R3: PARAM_MONITOR_DATA_STR | S3: CPU2 | T3: 1 | U3: STRING | V3: 2：UPM进行轮询 | W3: 系统参数2 | X3: 2
A4: 机器版本号 | B4: ParamClientCode | C4: Sys_U16 | E4: 0 | F4: 2 | G4: 10 | H4: 20 | I4: 0 | J4: 65535 | K4: 0 | M4: RO | N4: N | O4: Y | P4: N | Q4: Y | R4: PARAM_MONITOR_DATA_STR | S4: CPU2 | T4: 1 | U4: STRING | V4: 2：UPM进行轮询 | W4: 系统参数2 | X4: 2
A5: 机器型号编码 | B5: ParamType | C5: Sys_U16 | E5: 0 | F5: 2 | G5: 1 | H5: 2 | I5: 0 | J5: 65535 | K5: 0 | M5: RO | N5: N | O5: Y | P5: N | Q5: Y | R5: PARAM_MONITOR_DATA_STR | S5: CPU2 | T5: 1 | U5: U16 | V5: 2：UPM进行轮询 | W5: 系统参数2 | X5: 2
A6: 设备类型编码 | B6: ParamMatrilCode | C6: Sys_U16 | E6: 0 | F6: 2 | G6: 1 | H6: 2 | I6: 0 | J6: 65535 | K6: 0 | M6: RO | N6: N | O6: Y | P6: N | Q6: Y | R6: PARAM_MONITOR_DATA_STR | S6: CPU2 | T6: 1 | U6: U16 | V6: 2：UPM进行轮询 | W6: 系统参数2 | X6: 2
A7: DCDC任务级故障字1 | B7: DcdcTskFwFltFlg1 | C7: Sys_U16 | D7: bit0:RECT1温度过温 bit1:RECT2温度过温 bit2:BST温度过温 bit3:Buck温度过温 bit4:环境温度过温 bit5:预留5 bit6:电网缺相 bit7:Rect输出母线过压 bit8:Rect输出母线欠压 bit9:Boost输出母线过压 bit10:Boost输出母线欠压 bit11:Buck输出母线过压 bit12:Buck输出母线欠压 bit13:Can通信超时 bit14:预留14 bit15:预留15 | E7: 0 | F7: 2 | G7: 1 | H7: 2 | I7: 0 | J7: 65535 | K7: 0 | M7: RO | N7: N | O7: Y | P7: N | Q7: Y | R7: PARAM_MONITOR_DATA_STR | S7: CPU2 | T7: 1 | U7: U16 | V7: 3：CSU进行轮询 | W7: 任务级观测量 | X7: 99
A8: DCDC任务级故障字2 | B8: DcdcTskFwFltFlg2 | C8: Sys_U16 | D8: bit0:BST1过流 bit1:BST2过流 bit2:BST3过流 bit3:BST4过流 bit4:BUCK1过流 bit5:BUCK2过流 bit6:BUCK3过流 bit7:BUCK4过流 bit8:预留8 bit9:预留9 bit10:预留10 bit11:预留11 bit12:预留12 bit13:预留13 bit14:预留14 bit15:预留15 | E8: 0 | F8: 2 | G8: 1 | H8: 2 | I8: 0 | J8: 65535 | K8: 0 | M8: RO | N8: N | O8: Y | P8: N | Q8: Y | R8: PARAM_MONITOR_DATA_STR | S8: CPU2 | T8: 1 | U8: U16 | V8: 2：UPM进行轮询 | W8: 任务级观测量 | X8: 99
A9: DCDC任务级故障字3 | B9: DcdcTskFwFltFlg3 | C9: Sys_U16 | D9: bit0:输出过流 bit1:预留1 bit2:RECT1温度NTC异常 bit3:RECT2温度NTC异常 bit4:BST温度NTC异常 bit5:BUCK温度NTC异常 bit6:环境温度NTC异常 bit7:功率继电器开路 bit8:功率继电器粘连 bit9:风扇1转速异常 bit10:风扇2转速异常 bit11:风扇3转速异常 bit12:晶闸管故障 bit13:电池IGBT故障 bit14:预留14 bit15:预留15 | E9: 0 | F9: 2 | G9: 1 | H9: 2 | I9: 0 | J9: 65535 | K9: 0 | M9: RO | N9: N | O9: Y | P9: N | Q9: Y | R9: PARAM_MONITOR_DATA_STR | S9: CPU2 | T9: 1 | U9: U16 | V9: 2：UPM进行轮询 | W9: 任务级观测量 | X9: 99
A10: DCDC任务级故障字4 | B10: DcdcTskFwFltFlg4 | C10: Sys_U16 | D10: bit0:预充超时 bit1:预留1 bit2:预留2 bit3:预留3 bit4:预留4 bit5:预留5 bit6:预留6 bit7:预留7 bit8:预留8 bit9:预留9 bit10:预留10 bit11:预留11 bit12:预留12 bit13:预留13 bit14:预留14 bit15:预留15 | E10: 0 | F10: 2 | G10: 1 | H10: 2 | I10: 0 | J10: 65535 | K10: 0 | M10: RO | N10: N | O10: Y | P10: N | Q10: Y | R10: PARAM_MONITOR_DATA_STR | S10: CPU2 | T10: 1 | U10: U16 | V10: 2：UPM进行轮询 | W10: 任务级观测量 | X10: 99
A11: DCDC任务级告警字1 | B11: DcdcTskWarnFltFlg1 | C11: Sys_U16 | D11: bit0:RECT1温度过温 bit1:RECT2温度过温 bit2:BST温度过温 bit3:Buck温度过温 bit4:环境温度过温 bit5:预留5 bit6:电网R相电压过压 bit7:电网S相电压过压 bit8:电网T相电压过压 bit9:电网R相电压欠压 bit10:电网S相电压欠压 bit11:电网T相电压欠压 bit12:电网过频 bit13:电网欠频 bit14:电池过压 bit15:电池欠压 | E11: 0 | F11: 2 | G11: 1 | H11: 2 | I11: 0 | J11: 65535 | K11: 0 | M11: RO | N11: N | O11: Y | P11: N | Q11: Y | R11: PARAM_MONITOR_DATA_STR | S11: CPU2 | T11: 1 | U11: U16 | V11: 2：UPM进行轮询 | W11: 任务级观测量 | X11: 99
A12: DCDC任务级告警字2 | B12: DcdcTskWarnFltFlg2 | C12: Sys_U16 | D12: bit0:RECT1温度NTC异常 bit1:RECT2温度NTC异常 bit2:BST温度NTC异常 bit3:BUCK温度NTC异常 bit4:环境温度NTC异常 bit5:功率继电器开路 bit6:功率继电器粘连 bit7:风扇1转速异常 bit8:风扇2转速异常 bit9:风扇3转速异常 bit10:晶闸管故障 bit11:电池IGBT故障 bit12:Can通信超时 bit13:输出过载降额 bit14:预留14 bit15:输出过流 | E12: 0 | F12: 2 | G12: 1 | H12: 2 | I12: 0 | J12: 65535 | K12: 0 | M12: RO | N12: N | O12: Y | P12: N | Q12: Y | R12: PARAM_MONITOR_DATA_STR | S12: CPU2 | T12: 1 | U12: U16 | V12: 2：UPM进行轮询 | W12: 任务级观测量 | X12: 99
A13: DCDC任务级告警字3 | B13: DcdcTskWarnFltFlg3 | C13: Sys_U16 | D13: bit0:预充超时 bit1:RECT1温度降额 bit2:RECT2温度降额 bit3:BST温度降额 bit4:BUCK温度降额 bit5:环境温度降额 bit6:海拔降额 bit7:CellID识别错误 bit8:预留8 bit9:预留9 bit10:预留10 bit11:预留11 bit12:预留12 bit13:预留13 bit14:预留14 bit15:预留15 | E13: 0 | F13: 2 | G13: 1 | H13: 2 | I13: 0 | J13: 65535 | K13: 0 | M13: RO | N13: N | O13: Y | P13: N | Q13: Y | R13: PARAM_MONITOR_DATA_STR | S13: CPU2 | T13: 1 | U13: U16 | V13: 2：UPM进行轮询 | W13: 任务级观测量 | X13: 99
A14: 主状态机工作模式 | B14: MainWrkMode | C14: Sys_U16 | D14: 0: Init 1: Standby 2: Work 3: Fault 4: off 5: OpenPrecharge 6: OpenLoopWrk | E14: 0 | F14: 2 | G14: 1 | H14: 2 | I14: 0 | J14: 500 | K14: 0 | M14: RO | N14: N | O14: Y | P14: N | Q14: Y | R14: PARAM_MONITOR_DATA_STR | S14: CPU2 | T14: 1 | U14: U16 | V14: 2：UPM进行轮询 | W14: 任务级观测量 | X14: 99
A15: 不控整流输出侧预充继电器闭合指令 | B15: U16_RLYBSTEn | C15: Sys_U16 | D15: 0:不使能 1:使能 2:降损 | E15: 0 | F15: 2 | G15: 1 | H15: 2 | I15: 0 | J15: 99 | K15: 0 | M15: RO | N15: N | O15: Y | P15: N | Q15: Y | R15: PARAM_MONITOR_DATA_STR | S15: CPU2 | T15: 1 | U15: U16 | V15: 1：上传至UPM | W15: 任务级观测量 | X15: 99
A16: Boost输出侧预充继电器闭合指令 | B16: U16_RLYBUSEn | C16: Sys_U16 | D16: 0:不使能 1:使能 | E16: 0 | F16: 2 | G16: 1 | H16: 2 | I16: 0 | J16: 99 | K16: 0 | M16: RO | N16: N | O16: Y | P16: N | Q16: Y | R16: PARAM_MONITOR_DATA_STR | S16: CPU2 | T16: 1 | U16: U16 | V16: 1：上传至UPM | W16: 任务级观测量 | X16: 99
A17: 输出侧预充继电器闭合指令 | B17: U16_RLYOUTEn | C17: Sys_U16 | D17: 0:不使能 1:使能 | E17: 0 | F17: 2 | G17: 1 | H17: 2 | I17: 0 | J17: 99 | K17: 0 | M17: RO | N17: N | O17: Y | P17: N | Q17: Y | R17: PARAM_MONITOR_DATA_STR | S17: CPU2 | T17: 1 | U17: U16 | V17: 1：上传至UPM | W17: 任务级观测量 | X17: 99
A18: Cell类型 | B18: U16_CellType | C18: Sys_U16 | D18: 0:UNDEF 1:CHARGER_CELL 2:POWER_CELL1 3:POWER_CELL2 4:POWER_CELL3 5:POWER_CELL4 6:POWER_CELL5 7:POWER_CELL6 8:POWER_CELL7 | E18: 0 | F18: 2 | G18: 1 | H18: 2 | I18: 0 | J18: 1 | K18: 0 | M18: RO | N18: N | O18: Y | P18: N | Q18: Y | R18: PARAM_MONITOR_DATA_STR | S18: CPU2 | T18: 1 | U18: U16 | V18: 1：上传至UPM | W18: 任务级观测量 | X18: 99
A19: DCDC中断负载运行总时间 | B19: DcdcIntLoadTotalRunTm | C19: Sys_F32 | E19: 8 | F19: 4 | G19: 1 | H19: 4 | I19: 0.00000000 | J19: 5.00000000 | K19: 0.00000000 | M19: RO | N19: N | O19: Y | P19: N | Q19: Y | R19: PARAM_MONITOR_DATA_STR | S19: CPU2 | T19: 1e-08 | U19: S32 | V19: 1：上传至UPM | W19: 任务级观测量 | X19: 99
A20: RECT1温度降额系数输出值 | B20: Rect1TemDerateCoffOut | C20: Sys_F32 | E20: 2 | F20: 4 | G20: 1 | H20: 4 | I20: 1.50 | J20: 2.00 | K20: 0.00 | M20: RO | N20: N | O20: Y | P20: N | Q20: Y | R20: PARAM_MONITOR_DATA_STR | S20: CPU2 | T20: 0.01 | U20: S32 | V20: 1：上传至UPM | W20: 任务级观测量 | X20: 99
A21: RECT2温度降额系数输出值 | B21: Rect2TemDerateCoffOut | C21: Sys_F32 | E21: 2 | F21: 4 | G21: 1 | H21: 4 | I21: 1.50 | J21: 2.00 | K21: 0.00 | M21: RO | N21: N | O21: Y | P21: N | Q21: Y | R21: PARAM_MONITOR_DATA_STR | S21: CPU2 | T21: 0.01 | U21: S32 | V21: 1：上传至UPM | W21: 任务级观测量 | X21: 99
A22: BST温度降额系数输出值 | B22: BstTemDerateCoffOut | C22: Sys_F32 | E22: 2 | F22: 4 | G22: 1 | H22: 4 | I22: 1.50 | J22: 2.00 | K22: 0.00 | M22: RO | N22: N | O22: Y | P22: N | Q22: Y | R22: PARAM_MONITOR_DATA_STR | S22: CPU2 | T22: 0.01 | U22: S32 | V22: 1：上传至UPM | W22: 任务级观测量 | X22: 99
A23: BUCK温度降额系数输出值 | B23: BuckTemDerateCoffOut | C23: Sys_F32 | E23: 2 | F23: 4 | G23: 1 | H23: 4 | I23: 1.50 | J23: 2.00 | K23: 0.00 | M23: RO | N23: N | O23: Y | P23: N | Q23: Y | R23: PARAM_MONITOR_DATA_STR | S23: CPU2 | T23: 0.01 | U23: S32 | V23: 1：上传至UPM | W23: 任务级观测量 | X23: 99
A24: 环境温度降额系数输出值 | B24: AmbTemDerateCoffOut | C24: Sys_F32 | E24: 2 | F24: 4 | G24: 1 | H24: 4 | I24: 1.50 | J24: 2.00 | K24: 0.00 | M24: RO | N24: N | O24: Y | P24: N | Q24: Y | R24: PARAM_MONITOR_DATA_STR | S24: CPU2 | T24: 0.01 | U24: S32 | V24: 1：上传至UPM | W24: 任务级观测量 | X24: 99
A25: 输出过载降额系数输出值 | B25: OutputOverloadDerateCoffOut | C25: Sys_F32 | E25: 2 | F25: 4 | G25: 1 | H25: 4 | I25: 1.50 | J25: 2.00 | K25: 0.00 | M25: RO | N25: N | O25: Y | P25: N | Q25: Y | R25: PARAM_MONITOR_DATA_STR | S25: CPU2 | T25: 0.01 | U25: S32 | V25: 1：上传至UPM | W25: 任务级观测量 | X25: 99
A26: 总降额系数输出值 | B26: TotalDerateCoffOut | C26: Sys_F32 | E26: 2 | F26: 4 | G26: 1 | H26: 4 | I26: 1.50 | J26: 2.00 | K26: 0.00 | M26: RO | N26: N | O26: Y | P26: N | Q26: Y | R26: PARAM_MONITOR_DATA_STR | S26: CPU2 | T26: 0.01 | U26: S32 | V26: 1：上传至UPM | W26: 任务级观测量 | X26: 99
A27: 降额模块输出限流值 | B27: TotalDerateCurrLmt | C27: Sys_F32 | E27: 2 | F27: 4 | G27: 1 | H27: 4 | I27: 1.50 | J27: 2.00 | K27: 0.00 | M27: RO | N27: N | O27: Y | P27: N | Q27: Y | R27: PARAM_MONITOR_DATA_STR | S27: CPU2 | T27: 0.01 | U27: S32 | V27: 1：上传至UPM | W27: 任务级观测量 | X27: 99
A28: RECT1采样温度 | B28: F32_Rect1Tem | C28: Sys_F32 | E28: 2 | F28: 4 | G28: 1 | H28: 4 | I28: 0.00 | J28: 200.00 | K28: -100.00 | L28: ℃ | M28: RO | N28: N | O28: Y | P28: N | Q28: Y | R28: PARAM_MONITOR_DATA_STR | S28: CPU2 | T28: 0.01 | U28: S32 | V28: 1：上传至UPM | W28: 任务级观测量 | X28: 99
A29: RECT2采样温度 | B29: F32_Rect2Tem | C29: Sys_F32 | E29: 2 | F29: 4 | G29: 1 | H29: 4 | I29: 0.00 | J29: 200.00 | K29: -100.00 | L29: ℃ | M29: RO | N29: N | O29: Y | P29: N | Q29: Y | R29: PARAM_MONITOR_DATA_STR | S29: CPU2 | T29: 0.01 | U29: S32 | V29: 1：上传至UPM | W29: 任务级观测量 | X29: 99
A30: BST采样温度 | B30: F32_BstTem | C30: Sys_F32 | E30: 2 | F30: 4 | G30: 1 | H30: 4 | I30: 0.00 | J30: 200.00 | K30: -100.00 | L30: ℃ | M30: RO | N30: N | O30: Y | P30: N | Q30: Y | R30: PARAM_MONITOR_DATA_STR | S30: CPU2 | T30: 0.01 | U30: S32 | V30: 1：上传至UPM | W30: 任务级观测量 | X30: 99
A31: BUCK采样温度 | B31: F32_BuckTem | C31: Sys_F32 | E31: 2 | F31: 4 | G31: 1 | H31: 4 | I31: 0.00 | J31: 200.00 | K31: -100.00 | L31: ℃ | M31: RO | N31: N | O31: Y | P31: N | Q31: Y | R31: PARAM_MONITOR_DATA_STR | S31: CPU2 | T31: 0.01 | U31: S32 | V31: 1：上传至UPM | W31: 任务级观测量 | X31: 99
A32: 环境采样温度 | B32: F32_AmbTem | C32: Sys_F32 | E32: 2 | F32: 4 | G32: 1 | H32: 4 | I32: 0.00 | J32: 200.00 | K32: -100.00 | L32: ℃ | M32: RO | N32: N | O32: Y | P32: N | Q32: Y | R32: PARAM_MONITOR_DATA_STR | S32: CPU2 | T32: 0.01 | U32: S32 | V32: 1：上传至UPM | W32: 任务级观测量 | X32: 99
A33: 自定义整型观测信号1 | B33: U16_Test_Sgnl1Mea | C33: Sys_U16 | E33: 0 | F33: 2 | G33: 1 | H33: 2 | I33: 0 | J33: 65535 | K33: 0 | M33: RO | N33: N | O33: Y | P33: N | Q33: Y | R33: PARAM_MONITOR_DATA_STR | S33: CPU2 | T33: 1 | U33: U16 | V33: 1：上传至UPM | W33: 任务级观测量 | X33: 99
A34: 自定义整型观测信号2 | B34: U16_Test_Sgnl2Mea | C34: Sys_U16 | E34: 0 | F34: 2 | G34: 1 | H34: 2 | I34: 0 | J34: 65535 | K34: 0 | M34: RO | N34: N | O34: Y | P34: N | Q34: Y | R34: PARAM_MONITOR_DATA_STR | S34: CPU2 | T34: 1 | U34: U16 | V34: 1：上传至UPM | W34: 任务级观测量 | X34: 99
A35: 自定义整型观测信号3 | B35: U16_Test_Sgnl3Mea | C35: Sys_U16 | E35: 0 | F35: 2 | G35: 1 | H35: 2 | I35: 0 | J35: 65535 | K35: 0 | M35: RO | N35: N | O35: Y | P35: N | Q35: Y | R35: PARAM_MONITOR_DATA_STR | S35: CPU2 | T35: 1 | U35: U16 | V35: 1：上传至UPM | W35: 任务级观测量 | X35: 99
A36: 自定义整型观测信号4 | B36: U16_Test_Sgnl4Mea | C36: Sys_U16 | E36: 0 | F36: 2 | G36: 1 | H36: 2 | I36: 0 | J36: 65535 | K36: 0 | M36: RO | N36: N | O36: Y | P36: N | Q36: Y | R36: PARAM_MONITOR_DATA_STR | S36: CPU2 | T36: 1 | U36: U16 | V36: 1：上传至UPM | W36: 任务级观测量 | X36: 99
A37: 自定义整型观测信号5 | B37: U16_Test_Sgnl5Mea | C37: Sys_U16 | E37: 0 | F37: 2 | G37: 1 | H37: 2 | I37: 0 | J37: 65535 | K37: 0 | M37: RO | N37: N | O37: Y | P37: N | Q37: Y | R37: PARAM_MONITOR_DATA_STR | S37: CPU2 | T37: 1 | U37: U16 | V37: 1：上传至UPM | W37: 任务级观测量 | X37: 99
A38: 自定义整型观测信号6 | B38: U16_Test_Sgnl6Mea | C38: Sys_U16 | E38: 0 | F38: 2 | G38: 1 | H38: 2 | I38: 0 | J38: 65535 | K38: 0 | M38: RO | N38: N | O38: Y | P38: N | Q38: Y | R38: PARAM_MONITOR_DATA_STR | S38: CPU2 | T38: 1 | U38: U16 | V38: 1：上传至UPM | W38: 任务级观测量 | X38: 99
A39: 自定义整型观测信号7 | B39: U16_Test_Sgnl7Mea | C39: Sys_U16 | E39: 0 | F39: 2 | G39: 1 | H39: 2 | I39: 0 | J39: 65535 | K39: 0 | M39: RO | N39: N | O39: Y | P39: N | Q39: Y | R39: PARAM_MONITOR_DATA_STR | S39: CPU2 | T39: 1 | U39: U16 | V39: 1：上传至UPM | W39: 任务级观测量 | X39: 99
A40: 自定义整型观测信号8 | B40: U16_Test_Sgnl8Mea | C40: Sys_U16 | E40: 0 | F40: 2 | G40: 1 | H40: 2 | I40: 0 | J40: 65535 | K40: 0 | M40: RO | N40: N | O40: Y | P40: N | Q40: Y | R40: PARAM_MONITOR_DATA_STR | S40: CPU2 | T40: 1 | U40: U16 | V40: 1：上传至UPM | W40: 任务级观测量 | X40: 99
...

Sheet UPM-DSP采集数据
A1: 数据定义 | B1: ENMU | C1: 数据类型 | D1: 离散值逻辑 | E1: 数据 长度 | F1: 默认值 | G1: 数据上限 | H1: 数据下限 | I1: 单位 | J1: 读写 权限 | K1: 精度 | L1: 数据上传 等级 | M1: UPP模型 名称 | N1: UPP地址 | O1: UPP偏移 | P1: arm 配置参数 | Q1: UPP 轮询间隔 | R1: 设置 优先级 | S1: 轮询 优先级 | T1: 回调函数 | U1: signID | V1: modbus 地址 | W1: 备注 | X1: CSU UPP模型号 | AA1: =COUNTA(A2:A437) -> 436
A2: {=SORTBY(IF(CHOOSECOLS(_xlfn.FILTER('DSP内部数据'!$A$2:$X$5009,'DSP内部数据'!$V$2:$V$5009<>"0：不上传"),1,2,21,4,8,9,10,11,12,13,20,22,23,24)="","",CHOOSECOLS(_xlfn.FILTER('DSP内部数据'!$A$2:$X$5009,'DSP内部数据'!$V$2:$V$5009<>"0：不上传"),1,2,21,4,8,9,10,11,12,13,20,22,23,24)),_xlfn.FILTER('DSP内部数据'!$X$2:$X$5009,'DSP内部数据'!$V$2:$V$5009<>"0：不上传"),1,_xlfn.FILTER('DSP内部数据'!$V$2:$V$5009,'DSP内部数据'!$V$2:$V$5009<>"0：不上传"),-1)} -> 固件版本号版本 | B2: ParamProductType | C2: STRING | E2: 30 | F2: 0 | G2: 65534 | H2: 0 | J2: RO | K2: 1 | L2: 2：UPM进行轮询 | M2: 系统参数1 | N2: 1 | O2: {=_xlfn.FILTER(_xlfn.SWITCH($A$2:$A$4896,"固件版本号版本",48,"机器型号",8,"机器版本号",24,"序列号",62,"机器型号编码",94,"设备类型编码",96,6+SUMIF(ROW($E$2:$E$4896),"<"&ROW($E$2:$E$4896),$E$2:$E$4896)-_xlfn.XLOOKUP($N$2:$N$4896,$N$2:$N$4896,SUMIF(ROW($E$2:$E$4896),"<"&ROW($E$2:$E$4896),$E$2:$E$4896),0)),$N$2:$N$4896<>"")} -> 48 | P2: {=_xlfn.FILTER(IF(ISNUMBER(MATCH($L$2:$L$4896,{"2：UPM进行轮询","3：CSU进行轮询"},0)),_xlfn.XLOOKUP($A$2:$A$4896,'UPM-DSP手动配置数据'!$A$2:$A$5005,'UPM-DSP手动配置数据'!$C$2:$H$5005,"#NOT_FOUND"),"※"),$A$2:$A$4896<>"")} -> 0 | Q2: 205 | R2: 0 | S2: 0 | T2: NULL | U2: 2582 | V2: {=_xlfn.FILTER(SUMIF(ROW($E$2:$E$4896),"<"&ROW($E$2:$E$4896),$E$2:$E$4896)/2,$E$2:$E$4896<>"")} -> 0 | X2: {=_xlfn.FILTER((M$2:M$5000="系统参数1")*1+(M$2:M$5000="系统参数2")*2+(M$2:M$5000="任务级观测量")*99+(M$2:M$5000="中断级观测量")*100+(M$2:M$5000="控制参数设置")*102+(M$2:M$5000="任务级标定量")*103,M$2:M$5000<>"")} -> 1
A3: 机器型号 | B3: ParamProductCode | C3: STRING | E3: 16 | F3: 0 | G3: 65535 | H3: 0 | J3: RO | K3: 1 | L3: 2：UPM进行轮询 | M3: 系统参数2 | N3: 2 | O3: 8 | P3: 0 | Q3: 205 | R3: 0 | S3: 0 | T3: NULL | U3: 2516 | V3: 15 | X3: 2
A4: 机器版本号 | B4: ParamClientCode | C4: STRING | E4: 20 | F4: 0 | G4: 65535 | H4: 0 | J4: RO | K4: 1 | L4: 2：UPM进行轮询 | M4: 系统参数2 | N4: 2 | O4: 24 | P4: 0 | Q4: 205 | R4: 0 | S4: 0 | T4: NULL | U4: 2524 | V4: 23 | X4: 2
A5: 机器型号编码 | B5: ParamType | C5: U16 | E5: 2 | F5: 0 | G5: 65535 | H5: 0 | J5: RO | K5: 1 | L5: 2：UPM进行轮询 | M5: 系统参数2 | N5: 2 | O5: 94 | P5: 0 | Q5: 205 | R5: 0 | S5: 0 | T5: NULL | U5: 2515 | V5: 33 | X5: 2
A6: 设备类型编码 | B6: ParamMatrilCode | C6: U16 | E6: 2 | F6: 0 | G6: 65535 | H6: 0 | J6: RO | K6: 1 | L6: 2：UPM进行轮询 | M6: 系统参数2 | N6: 2 | O6: 96 | P6: 0 | Q6: 205 | R6: 0 | S6: 0 | T6: NULL | U6: 1481 | V6: 34 | X6: 2
A7: 序列号 | B7: ParamVehicleType | C7: STRING | E7: 20 | F7: 0 | G7: 65535 | H7: 0 | J7: RW | K7: 1 | L7: 2：UPM进行轮询 | M7: 系统参数2 | N7: 2 | O7: 62 | P7: 0 | Q7: 205 | R7: 0 | S7: 0 | T7: NULL | U7: 14 | V7: 35 | X7: 2
A8: DCDC任务级故障字1 | B8: DcdcTskFwFltFlg1 | C8: U16 | D8: bit0:RECT1温度过温 bit1:RECT2温度过温 bit2:BST温度过温 bit3:Buck温度过温 bit4:环境温度过温 bit5:预留5 bit6:电网缺相 bit7:Rect输出母线过压 bit8:Rect输出母线欠压 bit9:Boost输出母线过压 bit10:Boost输出母线欠压 bit11:Buck输出母线过压 bit12:Buck输出母线欠压 bit13:Can通信超时 bit14:预留14 bit15:预留15 | E8: 2 | F8: 0 | G8: 65535 | H8: 0 | J8: RO | K8: 1 | L8: 3：CSU进行轮询 | M8: 任务级观测量 | N8: 99 | O8: 6 | P8: 0 | Q8: 3 | R8: 0 | S8: 0 | T8: NULL | U8: 1007 | V8: 45 | X8: 99
A9: DCDC任务级故障字2 | B9: DcdcTskFwFltFlg2 | C9: U16 | D9: bit0:BST1过流 bit1:BST2过流 bit2:BST3过流 bit3:BST4过流 bit4:BUCK1过流 bit5:BUCK2过流 bit6:BUCK3过流 bit7:BUCK4过流 bit8:预留8 bit9:预留9 bit10:预留10 bit11:预留11 bit12:预留12 bit13:预留13 bit14:预留14 bit15:预留15 | E9: 2 | F9: 0 | G9: 65535 | H9: 0 | J9: RO | K9: 1 | L9: 2：UPM进行轮询 | M9: 任务级观测量 | N9: 99 | O9: 8 | P9: 0 | Q9: 3 | R9: 0 | S9: 0 | T9: NULL | U9: 1008 | V9: 46 | X9: 99
A10: DCDC任务级故障字3 | B10: DcdcTskFwFltFlg3 | C10: U16 | D10: bit0:输出过流 bit1:预留1 bit2:RECT1温度NTC异常 bit3:RECT2温度NTC异常 bit4:BST温度NTC异常 bit5:BUCK温度NTC异常 bit6:环境温度NTC异常 bit7:功率继电器开路 bit8:功率继电器粘连 bit9:风扇1转速异常 bit10:风扇2转速异常 bit11:风扇3转速异常 bit12:晶闸管故障 bit13:电池IGBT故障 bit14:预留14 bit15:预留15 | E10: 2 | F10: 0 | G10: 65535 | H10: 0 | J10: RO | K10: 1 | L10: 2：UPM进行轮询 | M10: 任务级观测量 | N10: 99 | O10: 10 | P10: 0 | Q10: 3 | R10: 0 | S10: 0 | T10: NULL | U10: 1009 | V10: 47 | X10: 99
A11: DCDC任务级故障字4 | B11: DcdcTskFwFltFlg4 | C11: U16 | D11: bit0:预充超时 bit1:预留1 bit2:预留2 bit3:预留3 bit4:预留4 bit5:预留5 bit6:预留6 bit7:预留7 bit8:预留8 bit9:预留9 bit10:预留10 bit11:预留11 bit12:预留12 bit13:预留13 bit14:预留14 bit15:预留15 | E11: 2 | F11: 0 | G11: 65535 | H11: 0 | J11: RO | K11: 1 | L11: 2：UPM进行轮询 | M11: 任务级观测量 | N11: 99 | O11: 12 | P11: 0 | Q11: 3 | R11: 0 | S11: 0 | T11: NULL | U11: 1010 | V11: 48 | X11: 99
A12: DCDC任务级告警字1 | B12: DcdcTskWarnFltFlg1 | C12: U16 | D12: bit0:RECT1温度过温 bit1:RECT2温度过温 bit2:BST温度过温 bit3:Buck温度过温 bit4:环境温度过温 bit5:预留5 bit6:电网R相电压过压 bit7:电网S相电压过压 bit8:电网T相电压过压 bit9:电网R相电压欠压 bit10:电网S相电压欠压 bit11:电网T相电压欠压 bit12:电网过频 bit13:电网欠频 bit14:电池过压 bit15:电池欠压 | E12: 2 | F12: 0 | G12: 65535 | H12: 0 | J12: RO | K12: 1 | L12: 2：UPM进行轮询 | M12: 任务级观测量 | N12: 99 | O12: 14 | P12: 0 | Q12: 3 | R12: 0 | S12: 0 | T12: NULL | U12: 1011 | V12: 49 | X12: 99
A13: DCDC任务级告警字2 | B13: DcdcTskWarnFltFlg2 | C13: U16 | D13: bit0:RECT1温度NTC异常 bit1:RECT2温度NTC异常 bit2:BST温度NTC异常 bit3:BUCK温度NTC异常 bit4:环境温度NTC异常 bit5:功率继电器开路 bit6:功率继电器粘连 bit7:风扇1转速异常 bit8:风扇2转速异常 bit9:风扇3转速异常 bit10:晶闸管故障 bit11:电池IGBT故障 bit12:Can通信超时 bit13:输出过载降额 bit14:预留14 bit15:输出过流 | E13: 2 | F13: 0 | G13: 65535 | H13: 0 | J13: RO | K13: 1 | L13: 2：UPM进行轮询 | M13: 任务级观测量 | N13: 99 | O13: 16 | P13: 0 | Q13: 3 | R13: 0 | S13: 0 | T13: NULL | U13: 1012 | V13: 50 | X13: 99
A14: DCDC任务级告警字3 | B14: DcdcTskWarnFltFlg3 | C14: U16 | D14: bit0:预充超时 bit1:RECT1温度降额 bit2:RECT2温度降额 bit3:BST温度降额 bit4:BUCK温度降额 bit5:环境温度降额 bit6:海拔降额 bit7:CellID识别错误 bit8:预留8 bit9:预留9 bit10:预留10 bit11:预留11 bit12:预留12 bit13:预留13 bit14:预留14 bit15:预留15 | E14: 2 | F14: 0 | G14: 65535 | H14: 0 | J14: RO | K14: 1 | L14: 2：UPM进行轮询 | M14: 任务级观测量 | N14: 99 | O14: 18 | P14: 0 | Q14: 3 | R14: 0 | S14: 0 | T14: NULL | U14: 1013 | V14: 51 | X14: 99
A15: 主状态机工作模式 | B15: MainWrkMode | C15: U16 | D15: 0: Init 1: Standby 2: Work 3: Fault 4: off 5: OpenPrecharge 6: OpenLoopWrk | E15: 2 | F15: 0 | G15: 500 | H15: 0 | J15: RO | K15: 1 | L15: 2：UPM进行轮询 | M15: 任务级观测量 | N15: 99 | O15: 20 | P15: 0 | Q15: 3 | R15: 0 | S15: 0 | T15: NULL | U15: 1014 | V15: 52 | X15: 99
A16: 不控整流输出侧预充继电器闭合指令 | B16: U16_RLYBSTEn | C16: U16 | D16: 0:不使能 1:使能 2:降损 | E16: 2 | F16: 0 | G16: 99 | H16: 0 | J16: RO | K16: 1 | L16: 1：上传至UPM | M16: 任务级观测量 | N16: 99 | O16: 22 | P16: ※ | Q16: ※ | R16: ※ | S16: ※ | T16: ※ | U16: ※ | V16: 53 | X16: 99
A17: Boost输出侧预充继电器闭合指令 | B17: U16_RLYBUSEn | C17: U16 | D17: 0:不使能 1:使能 | E17: 2 | F17: 0 | G17: 99 | H17: 0 | J17: RO | K17: 1 | L17: 1：上传至UPM | M17: 任务级观测量 | N17: 99 | O17: 24 | P17: ※ | Q17: ※ | R17: ※ | S17: ※ | T17: ※ | U17: ※ | V17: 54 | X17: 99
A18: 输出侧预充继电器闭合指令 | B18: U16_RLYOUTEn | C18: U16 | D18: 0:不使能 1:使能 | E18: 2 | F18: 0 | G18: 99 | H18: 0 | J18: RO | K18: 1 | L18: 1：上传至UPM | M18: 任务级观测量 | N18: 99 | O18: 26 | P18: ※ | Q18: ※ | R18: ※ | S18: ※ | T18: ※ | U18: ※ | V18: 55 | X18: 99
A19: Cell类型 | B19: U16_CellType | C19: U16 | D19: 0:UNDEF 1:CHARGER_CELL 2:POWER_CELL1 3:POWER_CELL2 4:POWER_CELL3 5:POWER_CELL4 6:POWER_CELL5 7:POWER_CELL6 8:POWER_CELL7 | E19: 2 | F19: 0 | G19: 1 | H19: 0 | J19: RO | K19: 1 | L19: 1：上传至UPM | M19: 任务级观测量 | N19: 99 | O19: 28 | P19: ※ | Q19: ※ | R19: ※ | S19: ※ | T19: ※ | U19: ※ | V19: 56 | X19: 99
A20: DCDC中断负载运行总时间 | B20: DcdcIntLoadTotalRunTm | C20: S32 | E20: 4 | F20: 0.00000000 | G20: 5.00000000 | H20: 0.00000000 | J20: RO | K20: 1e-08 | L20: 1：上传至UPM | M20: 任务级观测量 | N20: 99 | O20: 30 | P20: ※ | Q20: ※ | R20: ※ | S20: ※ | T20: ※ | U20: ※ | V20: 57 | X20: 99
A21: RECT1温度降额系数输出值 | B21: Rect1TemDerateCoffOut | C21: S32 | E21: 4 | F21: 1.50 | G21: 2.00 | H21: 0.00 | J21: RO | K21: 0.01 | L21: 1：上传至UPM | M21: 任务级观测量 | N21: 99 | O21: 34 | P21: ※ | Q21: ※ | R21: ※ | S21: ※ | T21: ※ | U21: ※ | V21: 59 | X21: 99
A22: RECT2温度降额系数输出值 | B22: Rect2TemDerateCoffOut | C22: S32 | E22: 4 | F22: 1.50 | G22: 2.00 | H22: 0.00 | J22: RO | K22: 0.01 | L22: 1：上传至UPM | M22: 任务级观测量 | N22: 99 | O22: 38 | P22: ※ | Q22: ※ | R22: ※ | S22: ※ | T22: ※ | U22: ※ | V22: 61 | X22: 99
A23: BST温度降额系数输出值 | B23: BstTemDerateCoffOut | C23: S32 | E23: 4 | F23: 1.50 | G23: 2.00 | H23: 0.00 | J23: RO | K23: 0.01 | L23: 1：上传至UPM | M23: 任务级观测量 | N23: 99 | O23: 42 | P23: ※ | Q23: ※ | R23: ※ | S23: ※ | T23: ※ | U23: ※ | V23: 63 | X23: 99
A24: BUCK温度降额系数输出值 | B24: BuckTemDerateCoffOut | C24: S32 | E24: 4 | F24: 1.50 | G24: 2.00 | H24: 0.00 | J24: RO | K24: 0.01 | L24: 1：上传至UPM | M24: 任务级观测量 | N24: 99 | O24: 46 | P24: ※ | Q24: ※ | R24: ※ | S24: ※ | T24: ※ | U24: ※ | V24: 65 | X24: 99
A25: 环境温度降额系数输出值 | B25: AmbTemDerateCoffOut | C25: S32 | E25: 4 | F25: 1.50 | G25: 2.00 | H25: 0.00 | J25: RO | K25: 0.01 | L25: 1：上传至UPM | M25: 任务级观测量 | N25: 99 | O25: 50 | P25: ※ | Q25: ※ | R25: ※ | S25: ※ | T25: ※ | U25: ※ | V25: 67 | X25: 99
A26: 输出过载降额系数输出值 | B26: OutputOverloadDerateCoffOut | C26: S32 | E26: 4 | F26: 1.50 | G26: 2.00 | H26: 0.00 | J26: RO | K26: 0.01 | L26: 1：上传至UPM | M26: 任务级观测量 | N26: 99 | O26: 54 | P26: ※ | Q26: ※ | R26: ※ | S26: ※ | T26: ※ | U26: ※ | V26: 69 | X26: 99
A27: 总降额系数输出值 | B27: TotalDerateCoffOut | C27: S32 | E27: 4 | F27: 1.50 | G27: 2.00 | H27: 0.00 | J27: RO | K27: 0.01 | L27: 1：上传至UPM | M27: 任务级观测量 | N27: 99 | O27: 58 | P27: ※ | Q27: ※ | R27: ※ | S27: ※ | T27: ※ | U27: ※ | V27: 71 | X27: 99
A28: 降额模块输出限流值 | B28: TotalDerateCurrLmt | C28: S32 | E28: 4 | F28: 1.50 | G28: 2.00 | H28: 0.00 | J28: RO | K28: 0.01 | L28: 1：上传至UPM | M28: 任务级观测量 | N28: 99 | O28: 62 | P28: ※ | Q28: ※ | R28: ※ | S28: ※ | T28: ※ | U28: ※ | V28: 73 | X28: 99
A29: RECT1采样温度 | B29: F32_Rect1Tem | C29: S32 | E29: 4 | F29: 0.00 | G29: 200.00 | H29: -100.00 | I29: ℃ | J29: RO | K29: 0.01 | L29: 1：上传至UPM | M29: 任务级观测量 | N29: 99 | O29: 66 | P29: ※ | Q29: ※ | R29: ※ | S29: ※ | T29: ※ | U29: ※ | V29: 75 | X29: 99
A30: RECT2采样温度 | B30: F32_Rect2Tem | C30: S32 | E30: 4 | F30: 0.00 | G30: 200.00 | H30: -100.00 | I30: ℃ | J30: RO | K30: 0.01 | L30: 1：上传至UPM | M30: 任务级观测量 | N30: 99 | O30: 70 | P30: ※ | Q30: ※ | R30: ※ | S30: ※ | T30: ※ | U30: ※ | V30: 77 | X30: 99
A31: BST采样温度 | B31: F32_BstTem | C31: S32 | E31: 4 | F31: 0.00 | G31: 200.00 | H31: -100.00 | I31: ℃ | J31: RO | K31: 0.01 | L31: 1：上传至UPM | M31: 任务级观测量 | N31: 99 | O31: 74 | P31: ※ | Q31: ※ | R31: ※ | S31: ※ | T31: ※ | U31: ※ | V31: 79 | X31: 99
A32: BUCK采样温度 | B32: F32_BuckTem | C32: S32 | E32: 4 | F32: 0.00 | G32: 200.00 | H32: -100.00 | I32: ℃ | J32: RO | K32: 0.01 | L32: 1：上传至UPM | M32: 任务级观测量 | N32: 99 | O32: 78 | P32: ※ | Q32: ※ | R32: ※ | S32: ※ | T32: ※ | U32: ※ | V32: 81 | X32: 99
A33: 环境采样温度 | B33: F32_AmbTem | C33: S32 | E33: 4 | F33: 0.00 | G33: 200.00 | H33: -100.00 | I33: ℃ | J33: RO | K33: 0.01 | L33: 1：上传至UPM | M33: 任务级观测量 | N33: 99 | O33: 82 | P33: ※ | Q33: ※ | R33: ※ | S33: ※ | T33: ※ | U33: ※ | V33: 83 | X33: 99
A34: 自定义整型观测信号1 | B34: U16_Test_Sgnl1Mea | C34: U16 | E34: 2 | F34: 0 | G34: 65535 | H34: 0 | J34: RO | K34: 1 | L34: 1：上传至UPM | M34: 任务级观测量 | N34: 99 | O34: 86 | P34: ※ | Q34: ※ | R34: ※ | S34: ※ | T34: ※ | U34: ※ | V34: 85 | X34: 99
A35: 自定义整型观测信号2 | B35: U16_Test_Sgnl2Mea | C35: U16 | E35: 2 | F35: 0 | G35: 65535 | H35: 0 | J35: RO | K35: 1 | L35: 1：上传至UPM | M35: 任务级观测量 | N35: 99 | O35: 88 | P35: ※ | Q35: ※ | R35: ※ | S35: ※ | T35: ※ | U35: ※ | V35: 86 | X35: 99
A36: 自定义整型观测信号3 | B36: U16_Test_Sgnl3Mea | C36: U16 | E36: 2 | F36: 0 | G36: 65535 | H36: 0 | J36: RO | K36: 1 | L36: 1：上传至UPM | M36: 任务级观测量 | N36: 99 | O36: 90 | P36: ※ | Q36: ※ | R36: ※ | S36: ※ | T36: ※ | U36: ※ | V36: 87 | X36: 99
A37: 自定义整型观测信号4 | B37: U16_Test_Sgnl4Mea | C37: U16 | E37: 2 | F37: 0 | G37: 65535 | H37: 0 | J37: RO | K37: 1 | L37: 1：上传至UPM | M37: 任务级观测量 | N37: 99 | O37: 92 | P37: ※ | Q37: ※ | R37: ※ | S37: ※ | T37: ※ | U37: ※ | V37: 88 | X37: 99
A38: 自定义整型观测信号5 | B38: U16_Test_Sgnl5Mea | C38: U16 | E38: 2 | F38: 0 | G38: 65535 | H38: 0 | J38: RO | K38: 1 | L38: 1：上传至UPM | M38: 任务级观测量 | N38: 99 | O38: 94 | P38: ※ | Q38: ※ | R38: ※ | S38: ※ | T38: ※ | U38: ※ | V38: 89 | X38: 99
A39: 自定义整型观测信号6 | B39: U16_Test_Sgnl6Mea | C39: U16 | E39: 2 | F39: 0 | G39: 65535 | H39: 0 | J39: RO | K39: 1 | L39: 1：上传至UPM | M39: 任务级观测量 | N39: 99 | O39: 96 | P39: ※ | Q39: ※ | R39: ※ | S39: ※ | T39: ※ | U39: ※ | V39: 90 | X39: 99
A40: 自定义整型观测信号7 | B40: U16_Test_Sgnl7Mea | C40: U16 | E40: 2 | F40: 0 | G40: 65535 | H40: 0 | J40: RO | K40: 1 | L40: 1：上传至UPM | M40: 任务级观测量 | N40: 99 | O40: 98 | P40: ※ | Q40: ※ | R40: ※ | S40: ※ | T40: ※ | U40: ※ | V40: 91 | X40: 99
...

Sheet UPM-DSP手动配置数据
A1: 数据定义 | B1: ENMU | C1: arm 配置参数 | D1: UPP 轮询间隔 | E1: 设置 优先级 | F1: 轮询 优先级 | G1: 回调函数 | H1: signID | I1: modbus 地址 | J1: 备注 | K1: =COUNTA(A2:A442) -> 42
A2: 固件版本号版本 | B2: ParamProductType | C2: 0 | D2: 205 | E2: 0 | F2: 0 | G2: NULL | H2: 2582
A3: 机器型号 | B3: ParamProductCode | C3: 0 | D3: 205 | E3: 0 | F3: 0 | G3: NULL | H3: 2516
A4: 机器版本号 | B4: ParamClientCode | C4: 0 | D4: 205 | E4: 0 | F4: 0 | G4: NULL | H4: 2524
A5: 序列号 | B5: ParamVehicleType | C5: 0 | D5: 205 | E5: 0 | F5: 0 | G5: NULL | H5: 14
A6: 机器型号编码 | B6: ParamType | C6: 0 | D6: 205 | E6: 0 | F6: 0 | G6: NULL | H6: 2515
A7: 设备类型编码 | B7: ParamMatrilCode | C7: 0 | D7: 205 | E7: 0 | F7: 0 | G7: NULL | H7: 1481
A8: DCDC任务级故障字1 | B8: DcdcTskFwFltFlg1 | C8: 0 | D8: 3 | E8: 0 | F8: 0 | G8: NULL | H8: 1007
A9: DCDC任务级故障字2 | B9: DcdcTskFwFltFlg2 | C9: 0 | D9: 3 | E9: 0 | F9: 0 | G9: NULL | H9: 1008
A10: DCDC任务级故障字3 | B10: DcdcTskFwFltFlg3 | C10: 0 | D10: 3 | E10: 0 | F10: 0 | G10: NULL | H10: 1009
A11: DCDC任务级故障字4 | B11: DcdcTskFwFltFlg4 | C11: 0 | D11: 3 | E11: 0 | F11: 0 | G11: NULL | H11: 1010
A12: DCDC任务级告警字1 | B12: DcdcTskWarnFltFlg1 | C12: 0 | D12: 3 | E12: 0 | F12: 0 | G12: NULL | H12: 1011
A13: DCDC任务级告警字2 | B13: DcdcTskWarnFltFlg2 | C13: 0 | D13: 3 | E13: 0 | F13: 0 | G13: NULL | H13: 1012
... A42: 风扇3转速 | B42: U16_FanSpeed3 | C42: 0 | D42: 3 | E42: 0 | F42: 0 | G42: NULL | H42: 1041
A43: 主控板平均电压 | B43: ARM_AverageVol

Sheet UPM板内Modbus地址分配
A1: 地址段功能 | B1: 地址段起点 | C1: 地址段终点
A2: IAPV3升级 | B2: 20050 | C2: 20104
A3: 自动搜索 | B3: 4800 | C3: 4899
A4: 故障录波 | B4: 15999 | C4: 17499
A5: 日志系统 | B5: 31999 | C5: 32100
A6: 故障录波系统 | B6: 30050 | C6: 30100
A7: arm监控板读取参数 | B7: 31000 | C7: 31900
A8: arm监控板设置参数 | B8: 41000 | C8: 41999
A9: 模块1 | B9: 50000 | C9: 50999
A10: 模块2 | B10: 51000 | C10: 51999
A11: 模块3 | B11: 52000 | C11: 52999
A12: 模块4 | B12: 53000 | C12: 53999
A13: 模块5 | B13: 54000 | C13: 54999
... A16: 模块8 | B16: 57000 | C16: 57999

Sheet 平台公共测点映射表
A1: 平台测点枚举 | B1: 平台测点值
A2: COMM_SIGID_TR_ADDR | B2: 1
A3: COMM_SIGID_VER_PUBLISH | B3: 6
A4: COMM_SIGID_VER_BUILD | B4: 7
A5: COMM_SIGID_VER_HOTFIX | B5: 8
A6: COMM_SIGID_VER_TAG | B6: 12
A7: COMM_SIGID_DEV_SN | B7: 14
A8: SIGID_UART_PORT1_WORKMODE | B8: 101
A9: SIGID_UART_PORT1_BAUD | B9: 102
A10: SIGID_UART_PORT1_PARITY | B10: 103
A11: SIGID_UART_PORT1_STOP_BITS | B11: 104
A12: SIGID_UART_PORT2_WORKMODE | B12: 105
A13: SIGID_UART_PORT2_BAUD | B13: 106
... A106: SIGID_DSP_DEV_SN_16 | B106: 345

Sheet CSU-UPM采集数据（暂时不用）
A1: 数据来源 | B1: 数据定义 | C1: ENMU | D1: 数据类型 | E1: 离散值逻辑 | F1: 数据 长度 | G1: 默认值 | H1: 数据上限 | I1: 数据下限 | J1: 单位 | K1: 读写 权限 | L1: 精度 | M1: 数据上传 等级 | N1: UPP模型 名称 | O1: UPP地址 | P1: UPP偏移 | Q1: arm 配置参数 | R1: UPP 轮询间隔 | S1: 设置 优先级 | T1: 轮询 优先级 | U1: 回调函数 | V1: signID | W1: modbus 地址 | X1: 备注
A2: UPM | B2: 模块负载电压 | C2: UPM_SIG_LOAD_VOL | D2: U16 | F2: 2 | J2: V | K2: RO | L2: 0.1 | M2: 3：CSU进行轮询 | N2: UPM上报信息 | O2: 131 | P2: 6 | Q2: 0 | R2: 1 | S2: 0 | T2: 0 | U2: NULL | V2: 2001
A3: UPM | B3: 模块负载电流 | C3: UPM_SIG_LOAD_CUR | D3: U16 | F3: 2 | J3: A | K3: RO | L3: 0.1 | M3: 3：CSU进行轮询 | N3: UPM上报信息 | O3: 131 | P3: 8 | Q3: 0 | R3: 1 | S3: 0 | T3: 0 | U3: NULL | V3: 2002
A4: UPM | B4: 电池电压 | C4: UPM_SIG_BAT_VOL | D4: U16 | F4: 2 | J4: V | K4: RO | L4: 0.1 | M4: 3：CSU进行轮询 | N4: UPM上报信息 | O4: 131 | P4: 10 | Q4: 0 | R4: 1 | S4: 0 | T4: 0 | U4: NULL | V4: 2003
A5: UPM | B5: 电池电流 | C5: UPM_SIG_BAT_CUR | D5: U16 | F5: 2 | J5: A | K5: RO | L5: 0.1 | M5: 3：CSU进行轮询 | N5: UPM上报信息 | O5: 131 | P5: 12 | Q5: 0 | R5: 1 | S5: 0 | T5: 0 | U5: NULL | V5: 2004
A6: UPM | B6: 模块交流线电压Uab | C6: UPM_SIG_UAB_VOL | D6: U16 | F6: 2 | J6: V | K6: RO | L6: 0.1 | M6: 3：CSU进行轮询 | N6: UPM上报信息 | O6: 131 | P6: 14 | Q6: 0 | R6: 1 | S6: 0 | T6: 0 | U6: NULL | V6: 2005
A7: UPM | B7: 模块交流线电压Ubc | C7: UPM_SIG_UBC_VOL | D7: U16 | F7: 2 | J7: V | K7: RO | L7: 0.1 | M7: 3：CSU进行轮询 | N7: UPM上报信息 | O7: 131 | P7: 16 | Q7: 0 | R7: 1 | S7: 0 | T7: 0 | U7: NULL | V7: 2006
A8: UPM | B8: 模块交流线电压Uca | C8: UPM_SIG_UCA_VOL | D8: U16 | F8: 2 | J8: V | K8: RO | L8: 0.1 | M8: 3：CSU进行轮询 | N8: UPM上报信息 | O8: 131 | P8: 18 | Q8: 0 | R8: 1 | S8: 0 | T8: 0 | U8: NULL | V8: 2007
A9: UPM | B9: 交流频率 | C9: UPM_SIG_AC_FREQ | D9: U16 | F9: 2 | J9: Hz | K9: RO | L9: 0.1 | M9: 3：CSU进行轮询 | N9: UPM上报信息 | O9: 131 | P9: 20 | Q9: 0 | R9: 1 | S9: 0 | T9: 0 | U9: NULL | V9: 2008
A10: UPM | B10: 模块温度 | C10: UPM_SIG_TEMP | D10: U16 | F10: 2 | J10: ℃ | K10: RO | L10: 0.1 | M10: 3：CSU进行轮询 | N10: UPM上报信息 | O10: 131 | P10: 22 | Q10: 0 | R10: 1 | S10: 0 | T10: 0 | U10: NULL | V10: 2009
A11: UPM | B11: 子板供电方式 | C11: UPM_SIG_POWER_MODE_STATE | D11: U16 | E11: bit0 - cell1 0-AC 1-DC bit1 - cell2 0-AC 1-DC bit2 - cell3 0-AC 1-DC bit3 - cell4 0-AC 1-DC bit4 - cell50-AC 1-DC bit5 - cell6 0-AC 1-DC bit6 - cell7 0-AC 1-DC bit7 - cell8 0-AC 1-DC | F11: 2 | K11: RO | M11: 3：CSU进行轮询 | N11: UPM状态信息 | O11: 132 | P11: 6 | Q11: 0 | R11: 1 | S11: 0 | T11: 0 | U11: NULL | V11: 2501
A12: UPM | B12: 子板开关机状态 | C12: UPM_SIG_POWER_ OFF_STATE | D12: U16 | E12: bit0- cell1 0-关机 1-开机 bit1 - cell2 0-关机 1-开机 bit2- cell3 0-关机 1-开机 bit3 - cell4 0-关机 1-开机 bit4- cell5 0-关机 1-开机 bit5 - cell6 0-关机 1-开机 bit6- cell7 0-关机 1-开机 bit7 - cell8 0-关机 1-开机 | F12: 2 | K12: RO | M12: 3：CSU进行轮询 | N12: UPM状态信息 | O12: 132 | P12: 8 | Q12: 0 | R12: 1 | S12: 0 | T12: 0 | U12: NULL | V12: 2502
A13: UPM | B13: 子板休眠状态 | C13: UPM_SIG_SLEEP_STATE | D13: U16 | E13: bit0- cell1 0-工作 bit1 - cell2 0-工作 1-休眠 bit2- cell3 0-工作 1-休眠 bit3 - cell4 0-工作 1-休眠 bit4- cell5 0-工作 1-休眠 bit5 - cell6 0-工作 1-休眠 bit6- cell7 0-工作 1-休眠 bit7 - cell8 0-工作 1-休眠 | F13: 2 | K13: RO | M13: 3：CSU进行轮询 | N13: UPM状态信息 | O13: 132 | P13: 10 | Q13: 0 | R13: 1 | S13: 0 | T13: 0 | U13: NULL | V13: 2503
A14: UPM | B14: 模块故障1模块故障1 | C14: UPM_SIG_FAULT_STATE1 | D14: U32 | E14: bit0 - 模块故障 bit1 -模块均流故障 bit2 -模块风扇故障 bit3 -模块过温 bit4-限流限功率 | F14: 4 | K14: RO | M14: 3：CSU进行轮询 | N14: UPM状态信息 | O14: 132 | P14: 12 | Q14: 0 | R14: 1 | S14: 0 | T14: 0 | U14: NULL | V14: 2504 | X14: 或关系
A15: UPM | B15: 模块交流故障 | C15: UPM_SIG_AC_FAULT_STATE | D15: U16 | E15: bit0 -模块交流线电压Uab高 bit1 -模块交流线电压Ubc高 bit2 -模块交流线电压Uca高 bit3 -模块交流线电压Uab低 bit4 -模块交流线电压Ubc低 bit5 -模块交流线电压Uca低 bit6 -模块交流中断 bit7 -模块交流频率高 bit8 -模块交流频率低 | F15: 2 | K15: RO | M15: 3：CSU进行轮询 | N15: UPM状态信息 | O15: 132 | P15: 16 | Q15: 0 | R15: 1 | S15: 0 | T15: 0 | U15: NULL | V15: 2505 | X15: 交流信息由UPM判断故障和非故障
A16: UPM | B16: 子板故障状态 | E16: bit0- cell1 0-正常 1-故障 bit1 - cell2 0-正常 1-故障 bit2- cell3 0-正常 1-故障 bit3 - cell4 0-正常 1-故障 bit4- cell5 0-正常 1-故障 bit5 - cell6 0-正常 1-故障 bit6- cell7 0-正常 1-故障 bit7 - cell8 0-正常 1-故障 | F16: 2 | K16: RO | M16: 3：CSU进行轮询 | N16: UPM状态信息 | O16: 132 | P16: 18 | Q16: 0 | R16: 1 | S16: 0 | T16: 0 | U16: NULL | V16: 2506
A17: UPM | B17: 负载输出电压设置 | C17: UPM_SIG_LOAD_VOL_SET | D17: U16 | F17: 2 | G17: 270 | J17: V | K17: RW | L17: 0.1 | M17: 3：CSU进行轮询 | N17: UPM设置参数 | O17: 133 | P17: 6 | Q17: 0 | R17: 30 | S17: 0 | T17: 0 | U17: NULL | V17: 3001
A18: UPM | B18: 负载输出限流值 | C18: UPM_SIG_LOAD_CUR_SET | D18: U16 | F18: 2 | G18: 100 | J18: A | K18: RW | L18: 0.1 | M18: 3：CSU进行轮询 | N18: UPM设置参数 | O18: 133 | P18: 8 | Q18: 0 | R18: 30 | S18: 0 | T18: 0 | U18: NULL | V18: 3002
A19: UPM | B19: 负载输出电压缺省值 | C19: UPM_SIG_LOAD_DEFAULT_VOL | D19: U16 | F19: 2 | G19: 270 | J19: V | K19: RW | L19: 0.1 | M19: 3：CSU进行轮询 | N19: UPM设置参数 | O19: 133 | P19: 10 | Q19: 0 | R19: 30 | S19: 0 | T19: 0 | U19: NULL | V19: 3003
A20: UPM | B20: 电池电压设置 | C20: UPM_SIG_BAT_VOL_SET | D20: U16 | F20: 2 | G20: 270 | J20: V | K20: RW | L20: 0.1 | M20: 3：CSU进行轮询 | N20: UPM设置参数 | O20: 133 | P20: 12 | Q20: 0 | R20: 30 | S20: 0 | T20: 0 | U20: NULL | V20: 3004 | X20: 不做广播
A21: UPM | B21: 电池限流设置 | C21: UPM_SIG_BAT_CUR_SET | D21: U16 | F21: 2 | G21: 10 | J21: A | K21: RW | L21: 0.1 | M21: 3：CSU进行轮询 | N21: UPM设置参数 | O21: 133 | P21: 14 | Q21: 0 | R21: 30 | S21: 0 | T21: 0 | U21: NULL | V21: 3005 | X21: 不做广播
A22: UPM | B22: 电池输出点电压缺省值 | C22: UPM_SIG_BAT_DEFAULT_VOL | D22: U16 | F22: 2 | G22: 270 | J22: V | K22: RW | L22: 0.1 | M22: 3：CSU进行轮询 | N22: UPM设置参数 | O22: 133 | P22: 16 | Q22: 0 | R22: 30 | S22: 0 | T22: 0 | U22: NULL | V22: 3006
A23: UPM | B23: 模块交流过压值 | C23: UPM_SIG_AC_OVER_VOL | D23: U16 | F23: 2 | G23: 420 | J23: V | K23: RW | L23: 0.1 | M23: 3：CSU进行轮询 | N23: UPM设置参数 | O23: 133 | P23: 18 | Q23: 0 | R23: 30 | S23: 0 | T23: 0 | U23: NULL | V23: 3007
A24: UPM | B24: 模块交流欠压值 | C24: UPM_SIG_AC_UNDER_VOL | D24: U16 | F24: 2 | G24: 370 | J24: V | K24: RW | L24: 0.1 | M24: 3：CSU进行轮询 | N24: UPM设置参数 | O24: 133 | P24: 20 | Q24: 0 | R24: 30 | S24: 0 | T24: 0 | U24: NULL | V24: 3008
A25: UPM | B25: 模块交流失压值 | C25: UPM_SIG_AC_NONE_VOL | D25: U16 | F25: 2 | G25: 170 | J25: V | K25: RW | L25: 0.1 | M25: 3：CSU进行轮询 | N25: UPM设置参数 | O25: 133 | P25: 22 | Q25: 0 | R25: 30 | S25: 0 | T25: 0 | U25: NULL | V25: 3009
A26: UPM | B26: 模块交流频率高门限值 | C26: UPM_SIG_AC_OVER_FREQ | D26: U16 | F26: 2 | G26: 70 | J26: Hz | K26: RW | L26: 0.1 | M26: 3：CSU进行轮询 | N26: UPM设置参数 | O26: 133 | P26: 24 | Q26: 0 | R26: 30 | S26: 0 | T26: 0 | U26: NULL | V26: 3010
A27: UPM | B27: 模块交流频率低门限值 | C27: UPM_SIG_AC_UNDER_FREQ | D27: U16 | F27: 2 | G27: 40 | J27: Hz | K27: RW | L27: 0.1 | M27: 3：CSU进行轮询 | N27: UPM设置参数 | O27: 133 | P27: 26 | Q27: 0 | R27: 30 | S27: 0 | T27: 0 | U27: NULL | V27: 3011
A28: UPM | B28: 开关机动作 | C28: UPM_SIG_POWER_OFF_CTRL | D28: U16 | E28: bit0 -cell1 0-开机 1-关机 bit1 -cell2 0-开机 1-关机 bit2 -cell3 0-开机 1-关机 bit3 -cell4 0-开机 1-关机 bit4 -cell5 0-开机 1-关机 bit5 -cell6 0-开机 1-关机 bit6 -cell7 0-开机 1-关机 bit7 -cell8 0-开机 1-关机 | F28: 2 | M28: 3：CSU进行轮询 | N28: UPM动作参数 | O28: 134 | P28: 6 | Q28: 0 | R28: 0 | S28: 0 | T28: 0 | U28: NULL | V28: 3501
A29: UPM | B29: 休眠动作 | C29: UPM_SIG_SLEEP_CTRL | D29: U16 | E29: bit0 -cell1 默认不允许参加休眠 bit1 -cell2 0-正常 1-休眠 bit2 -cell3 0-正常 1-休眠 bit3 -cell4 0-正常 1-休眠 bit4 -cell5 0-正常 1-休眠 bit5 -cell6 0-正常 1-休眠 bit6 -cell7 0-正常 1-休眠 bit7 -cell8 0-正常 1-休眠 | F29: 2 | M29: 3：CSU进行轮询 | N29: UPM动作参数 | O29: 134 | P29: 8 | Q29: 0 | R29: 0 | S29: 0 | T29: 0 | U29: NULL | V29: 3502
A30: UPM | B30: 子板供电动作 | C30: UPM_SIG_POWER_MODE_CTRL | D30: U16 | E30: bit0 - cell1 0-AC 1-DC bit1 - cell2 0-AC 1-DC bit2 - cell3 0-AC 1-DC bit3 - cell4 0-AC 1-DC bit4 - cell50-AC 1-DC bit5 - cell6 0-AC 1-DC bit6 - cell7 0-AC 1-DC bit7 - cell8 0-AC 1-DC | F30: 2 | M30: 3：CSU进行轮询 | N30: UPM动作参数 | O30: 134 | P30: 10 | Q30: 0 | R30: 0 | S30: 0 | T30: 0 | U30: NULL | V30: 3503
A31: CSU | B31: 模块交流空开状态 | C31: UPM_SIG_AC_SWITCH_STATE | D31: U16 | E31: 1=闭合;2=断开;3=跳闸 | F31: 2 | N31: CSU本地处理 | V31: 2010
A32: CSU | B32: 模块交流空开断开 | C32: UPM_SIG_AC_SWITCH_OFF | D32: U16 | E32: 1=告警;0=正常 | F32: 2 | N32: CSU本地处理 | V32: 2011
A33: CSU | B33: 模块状态 | C33: UPM_SIG_STATE | D33: U16 | E33: 0：正常 1：限流 2：限功率 3：关机 4：故障 5：通讯中断 6：未安装 7：休眠 8：过温 9：风扇故障 10：电池不在位 | F33: 2 | N33: CSU本地处理 | V33: 2012
A34: CSU | B34: 模块运行状态 | C34: UPM_SIG_RUN_STATE | D34: U16 | E34: bit0 - 模块故障 0 -告警1-正常 bit1 -开关机状态 0 -关机1-开机 bit2-模块通信故障 0-告警 1-正常 | F34: 2 | N34: CSU本地处理 | V34: 2013
A35: CSU | B35: 模块输出正极熔断器状态 | D35: U16 | E35: 1=告警;0=正常 | N35: CSU本地处理 | V35: 2014
A36: CSU | B36: 模块输出负极熔断器状态 | D36: U16 | E36: 1=告警;0=正常 | N36: CSU本地处理 | V36: 2015
A37: CSU | B37: 模块电池正极熔断器状态 | D37: U16 | E37: 1=告警;0=正常 | N37: CSU本地处理 | V37: 2016

Sheet iconfig使用
A1: 北向一级 分类 | B1: 北向二级 分类 | C1: 北向三级 分类 | D1: 定义 | E1: 离散值 逻辑 | F1: 默认值 | G1: 数据 上限 | H1: 数据 下限 | I1: 单位 | J1: 精度 | K1: 数据 类型 | L1: 读/写 | M1: 寄存器 类型 | N1: 寄存器 地址 | O1: 寄存器 长度 | P1: sigID
A2: {=VSTACK(_xlfn.FILTER('UPM单板测点'!$A$2:$A$4944,'UPM单板测点'!$O$2:$O$4944<>""),REPT("监控系统",SEQUENCE(COUNTA('UPM-DSP采集数据'!$A$2:$A$4732)*8,1,1,0)))} -> 监控系统 | B2: {=VSTACK(TOCOL("系统"&REPT("",SEQUENCE(1,'UPM单板测点'!$V$1))),TOCOL("模块"&SEQUENCE(1,8)&REPT("",SEQUENCE(ROWS(_xlfn.FILTER('UPM-DSP采集数据'!$A$2:$A$4732,'UPM-DSP采集数据'!$A$2:$A$4732<>"")),1))))} -> 系统 | C2: {=VSTACK(_xlfn.FILTER('UPM单板测点'!N$2:N$4944,'UPM单板测点'!O$2:O$4944<>""),TOCOL(_xlfn.FILTER('UPM-DSP采集数据'!M$2:M$4732,'UPM-DSP采集数据'!A$2:A$4732<>"")&REPT("",SEQUENCE(1,8))))} -> 通讯参数 | D2: {=VSTACK(IF(CHOOSECOLS(_xlfn.FILTER('UPM单板测点'!$A$2:$U$4944,'UPM单板测点'!$O$2:$O$4944<>""),2,3,4,5,6,7,8,9,10)="","",CHOOSECOLS(_xlfn.FILTER('UPM单板测点'!$A$2:$U$4944,'UPM单板测点'!$O$2:$O$4944<>""),2,3,4,5,6,7,8,9,10)),IF(INDEX(CHOOSECOLS(_xlfn.FILTER('UPM-DSP采集数据'!$A$2:$W$4896,'UPM-DSP采集数据'!$A$2:$A$4896<>""),1,4,6,7,8,9,11,3,10),ROUNDUP(SEQUENCE(ROWS(_xlfn.FILTER('UPM-DSP采集数据'!$A$2:$A$4896,'UPM-DSP采集数据'!$A$2:$A$4896<>""))*8)/8,0),SEQUENCE(1,9))="","",INDEX(CHOOSECOLS(_xlfn.FILTER('UPM-DSP采集数据'!$A$2:$W$4896,'UPM-DSP采集数据'!$A$2:$A$4896<>""),1,4,6,7,8,9,11,3,10),ROUNDUP(SEQUENCE(ROWS(_xlfn.FILTER('UPM-DSP采集数据'!$A$2:$A$4896,'UPM-DSP采集数据'!$A$2:$A$4896<>""))*8)/8,0),SEQUENCE(1,9))))} -> 设备转发地址 | F2: 0 | G2: 247 | H2: 0 | J2: 1 | K2: U16 | L2: RW | M2: {=_xlfn.FILTER(SUBSTITUTE(SUBSTITUTE(SUBSTITUTE($L$2:$L$3590,"RO","3x"),"RW","4x"),"WO","4x"),$L$2:$L$3590<>"")} -> 4x | N2: =VSTACK(_xlfn.FILTER('UPM单板测点'!$O$2:$O$4944,'UPM单板测点'!$O$2:$O$4944<>""),_xlfn.FILTER(_xlfn.XLOOKUP($D$2:$D$3590,'UPM-DSP采集数据'!$A$2:$A$4896,'UPM-DSP采集数据'!$V$2:$V$4896,0)+_xlfn.XLOOKUP($B$2:$B$3590,'UPM板内Modbus地址分配'!$A$2:$A$5000,'UPM板内Modbus地址分配'!$B$2:$B$5000,0),_xlfn.XLOOKUP($D$2:$D$3590,'UPM-DSP采集数据'!$A$2:$A$4896,'UPM-DSP采集数据'!$A$2:$A$4896,"")<>"")) | O2: {=VSTACK(_xlfn.FILTER('UPM单板测点'!K$2:K$4944,'UPM单板测点'!O$2:O$4944<>"")/2,--TOCOL((_xlfn.FILTER('UPM-DSP采集数据'!$E$2:$E$4732,'UPM-DSP采集数据'!$A$2:$A$4732<>"")/2)&REPT("",SEQUENCE(1,8))))} -> 1 | P2: {=VSTACK(_xlfn.FILTER('UPM单板测点'!Q$2:Q$4944,'UPM单板测点'!O$2:O$4944<>""),TOCOL(_xlfn.FILTER(LEFT('UPM-DSP采集数据'!$A$2:$A$4896,0)&REPT("",SEQUENCE(1,8)),'UPM-DSP采集数据'!$A$2:$A$4896<>""),0))} -> LOCAL_SIG_TR_ADDR
A3: 监控系统 | B3: 系统 | C3: 平台信息 | D3: 平台软件发布版本 | J3: 1 | K3: U16 | L3: RO | M3: 3x | O3: 1 | P3: LOCAL_SIG_VER_PUBLISH
A4: 监控系统 | B4: 系统 | C4: 平台信息 | D4: 平台软件构建版本 | J4: 1 | K4: U16 | L4: RO | M4: 3x | O4: 1 | P4: LOCAL_SIG_VER_BUILD
A5: 监控系统 | B5: 系统 | C5: 平台信息 | D5: 平台软件补丁版本 | J5: 1 | K5: U16 | L5: RO | M5: 3x | O5: 1 | P5: LOCAL_SIG_VER_HOTFIX
A6: 监控系统 | B6: 系统 | C6: 平台信息 | D6: 设备序列号 | J6: 1 | K6: STRING | L6: RW | M6: 4x | O6: 10 | P6: LOCAL_SIG_DEV_SN
A7: 监控系统 | B7: 系统 | C7: 设备信息 | D7: dsp的数量规格,修改该测点需要保证所有设备已经关机 | J7: 1 | K7: U16 | L7: RW | M7: 4x | O7: 1 | P7: LOCAL_SIG_DSP_DEV_NUM
A8: 监控系统 | B8: 系统 | C8: 设备信息 | D8: 查询DSP在线状态 | J8: 1 | K8: U16 | L8: RO | M8: 3x | O8: 1 | P8: LOCAL_SIG_DSP_ON_LINE_NUM
A9: 监控系统 | B9: 系统 | C9: 设备信息 | D9: 查询DSP在线状态 | J9: 1 | K9: U16 | L9: RO | M9: 3x | O9: 1 | P9: LOCAL_SIG_DSP_ON_LINE_NUM
A10: 监控系统 | B10: 系统 | C10: 设备信息 | D10: 查询DSP在线状态 | J10: 1 | K10: U16 | L10: RO | M10: 3x | O10: 1 | P10: LOCAL_SIG_DSP_ON_LINE_NUM
A11: 监控系统 | B11: 系统 | C11: 系统设置 | D11: NTP服务器 | J11: 1 | K11: STRING | L11: RW | M11: 4x | O11: 32 | P11: LOCAL_SIG_NTP_SERVER
A12: 监控系统 | B12: 系统 | C12: 系统设置 | D12: NTP对时时间间隔 单位:秒 | J12: 1 | K12: U32 | L12: RW | M12: 4x | O12: 2 | P12: LOCAL_SIG_NTP_TIME_INTERVAL
A13: 监控系统 | B13: 系统 | C13: 系统设置 | D13: NTP对时成功时间 | J13: 1 | K13: STRING | L13: RW | M13: 4x | O13: 16 | P13: LOCAL_SIG_NTP_SYNC_TIME
A14: 监控系统 | B14: 系统 | C14: 设备信息 | D14: 未绑定的DSP数量 | J14: 1 | K14: U16 | L14: RO | M14: 3x | O14: 1 | P14: LOCAL_SIG_NOT_BOUND_DSP_NUM
A15: 监控系统 | B15: 系统 | C15: 设备信息 | D15: 设备类型编码（北向机器型号编码） | F15: E_DEVTYPE_SGAIDC | J15: 1 | K15: U16 | L15: RO | M15: 3x | O15: 1 | P15: LOCAL_SIG_1481
A16: 故障录波系统 | B16: 系统 | C16: 故障录波系统 | D16: 北向 录波数据总条数30078 3x | J16: 1 | K16: U16 | L16: RO | M16: 3x | O16: 1 | P16: LOCAL_SIG_1621
A17: 故障录波系统 | B17: 系统 | C17: 故障录波系统 | D17: 北向 录波数据读取进度30079 3x | J17: 1 | K17: U16 | L17: RO | M17: 3x | O17: 1 | P17: LOCAL_SIG_1622
A18: 故障录波系统 | B18: 系统 | C18: 故障录波系统 | D18: 北向 整机属性协议号2500 3x | J18: 1 | K18: STRING | L18: RO | M18: 3x | O18: 2 | P18: LOCAL_SIG_2500
A19: 故障录波系统 | B19: 系统 | C19: 故障录波系统 | D19: 北向 整机属性协议版本2502 3x | J19: 1 | K19: U16 | L19: RO | M19: 3x | O19: 2 | P19: LOCAL_SIG_2502
A20: 故障录波系统 | B20: 系统 | C20: 故障录波系统 | D20: 北向 协议地址长度2504 3x | J20: 1 | K20: U16 | L20: RO | M20: 3x | O20: 1 | P20: LOCAL_SIG_2504
A21: 故障录波系统 | B21: 系统 | C21: 故障录波系统 | D21: 南向 机器型号30360 4x 北向 机器型号2516 3x | J21: 1 | K21: STRING | L21: RO | M21: 3x | O21: 8 | P21: LOCAL_SIG_2516
A22: 故障录波系统 | B22: 系统 | C22: 故障录波系统 | D22: 北向 故障录波协议号2569 3x | J22: 1 | K22: U32 | L22: RO | M22: 3x | O22: 2 | P22: LOCAL_SIG_2569
A23: 故障录波系统 | B23: 系统 | C23: 故障录波系统 | D23: 北向 故障录波协议版本2571 3x | J23: 1 | K23: U32 | L23: RO | M23: 3x | O23: 2 | P23: LOCAL_SIG_2571
A24: 监控系统 | B24: 系统 | C24: 设备信息 | D24: 北向 上传固件版本数量2581 3x | J24: 1 | K24: U16 | L24: RO | M24: 3x | O24: 1 | P24: LOCAL_SIG_2581
A25: 监控系统 | B25: 系统 | C25: 设备信息 | D25: 北向 固件版本号1 2582 3x | J25: 1 | K25: STRING | L25: RO | M25: 3x | O25: 15 | P25: LOCAL_SIG_VERSION
A26: 监控系统 | B26: 系统 | C26: 设备信息 | D26: 北向 固件版本号1 2582 3x | J26: 1 | K26: STRING | L26: RO | M26: 3x | O26: 15 | P26: LOCAL_SIG_VERSION
A27: 监控系统 | B27: 系统 | C27: 设备信息 | D27: 北向 固件版本号2 2597 3x | J27: 1 | K27: STRING | L27: RO | M27: 3x | O27: 15 | P27: LOCAL_SIG_2597
... A58: 日志系统 | B58: 系统 | C58: 日志系统 | D58: 北向 数据有效长度 4x | J58: 1 | K58: U16 | L58: RW | M58: 4x | O58: 1 | P58: LOCAL_SIG_32061
A59: 监控系统 | B59: 系统 | C59: 模块统计信息 | D59: 模块负载电压 | I59: V | J59: 0.1 | K59: U16 | L59: RO | M59: 3x | O59: 1 | P59: UPM_SIG_LOAD_VOL
A60: 监控系统 | B60: 系统 | C60: 模块统计信息 | D60: 模块负载电流 | I60: A | J60: 0.1 | K60: U16 | L60: RO | M60: 3x | O60: 1 | P60: UPM_SIG_LOAD_CUR
A61: 监控系统 | B61: 系统 | C61: 模块统计信息 | D61: 电池电压 | I61: V | J61: 0.1 | K61: U16 | L61: RO | M61: 3x | O61: 1 | P61: UPM_SIG_BAT_VOL
A62: 监控系统 | B62: 系统 | C62: 模块统计信息 | D62: 电池电流 | I62: A | J62: 0.1 | K62: U16 | L62: RO | M62: 3x | O62: 1 | P62: UPM_SIG_BAT_CUR
A63: 监控系统 | B63: 系统 | C63: 模块统计信息 | D63: 模块交流线电压Uab | I63: V | J63: 0.1 | K63: U16 | L63: RO | M63: 3x | O63: 1 | P63: UPM_SIG_UAB_VOL
A64: 监控系统 | B64: 系统 | C64: 模块统计信息 | D64: 模块交流线电压Ubc | I64: V | J64: 0.1 | K64: U16 | L64: RO | M64: 3x | O64: 1 | P64: UPM_SIG_UBC_VOL
A65: 监控系统 | B65: 系统 | C65: 模块统计信息 | D65: 模块交流线电压Uca | I65: V | J65: 0.1 | K65: U16 | L65: RO | M65: 3x | O65: 1 | P65: UPM_SIG_UCA_VOL
A66: 监控系统 | B66: 系统 | C66: 模块统计信息 | D66: 交流频率 | I66: Hz | J66: 0.1 | K66: U16 | L66: RO | M66: 3x | O66: 1 | P66: UPM_SIG_AC_FREQ
A67: 监控系统 | B67: 系统 | C67: 模块统计信息 | D67: 模块温度 | I67: ℃ | J67: 0.1 | K67: U16 | L67: RO | M67: 3x | O67: 1 | P67: UPM_SIG_TEMP
A68: 监控系统 | B68: 系统 | C68: 模块统计信息 | D68: 子板供电方式 | E68: bit0 - cell1 0-AC 1-DC bit1 - cell2 0-AC 1-DC bit2 - cell3 0-AC 1-DC bit3 - cell4 0-AC 1-DC bit4 - cell50-AC 1-DC bit5 - cell6 0-AC 1-DC bit6 - cell7 0-AC 1-DC bit7 - cell8 0-AC 1-DC | K68: U16 | L68: RO | M68: 3x | O68: 1 | P68: UPM_SIG_POWER_MODE_STATE
A69: 监控系统 | B69: 系统 | C69: 模块统计信息 | D69: 子板开关机状态 | E69: bit0- cell1 0-关机 1-开机 bit1 - cell2 0-关机 1-开机 bit2- cell3 0-关机 1-开机 bit3 - cell4 0-关机 1-开机 bit4- cell5 0-关机 1-开机 bit5 - cell6 0-关机 1-开机 bit6- cell7 0-关机 1-开机 bit7 - cell8 0-关机 1-开机 | K69: U16 | L69: RO | M69: 3x | O69: 1 | P69: UPM_SIG_POWER_ OFF_STATE
A70: 监控系统 | B70: 系统 | C70: 模块统计信息 | D70: 子板休眠状态 | E70: bit0- cell1 0-工作 bit1 - cell2 0-工作 1-休眠 bit2- cell3 0-工作 1-休眠 bit3 - cell4 0-工作 1-休眠 bit4- cell5 0-工作 1-休眠 bit5 - cell6 0-工作 1-休眠 bit6- cell7 0-工作 1-休眠 bit7 - cell8 0-工作 1-休眠 | K70: U16 | L70: RO | M70: 3x | O70: 1 | P70: UPM_SIG_SLEEP_STATE
...

Sheet UPM单板测点
A1: 系统分类 | B1: 数据定义 | C1: 离散值 逻辑 | D1: 默认值 | E1: 数据 上限 | F1: 数据 下限 | G1: 单位 | H1: 精度 | I1: 数据 类型 | J1: 读写 权限 | K1: 数据 长度 | L1: arm配置参数 | M1: 回调函数 | N1: 数据分类 | O1: modbus 地址 | P1: signID | Q1: ENMU | R1: 数据上传等级 | S1: 模型分类 | T1: 模型号 | U1: 备注 | V1: =COUNTA(O2:O4944) -> 86
A2: 监控系统 | B2: 设备转发地址 | D2: 0 | E2: 247 | F2: 0 | H2: 1 | I2: U16 | J2: RW | K2: 2 | L2: 5 | M2: NULL | N2: 通讯参数 | O2: 41654 | P2: COMM_SIGID_TR_ADDR | Q2: LOCAL_SIG_TR_ADDR | R2: 0：不上传 | S2: 模块统计信息 | U2: 寄存器类型=0x03；寄存器数量=1；转发说明=modbus设备地址(DCIM)
A3: 监控系统 | B3: 平台软件发布版本 | H3: 1 | I3: U16 | J3: RO | K3: 2 | L3: 0 | M3: NULL | N3: 平台信息 | O3: 2815 | P3: COMM_SIGID_VER_PUBLISH | Q3: LOCAL_SIG_VER_PUBLISH | R3: 0：不上传 | S3: 模块统计信息 | U3: 寄存器类型=0x04；寄存器数量=1；转发说明=平台软件发布版本 3x
A4: 监控系统 | B4: 平台软件构建版本 | H4: 1 | I4: U16 | J4: RO | K4: 2 | L4: 0 | M4: NULL | N4: 平台信息 | O4: 2816 | P4: COMM_SIGID_VER_BUILD | Q4: LOCAL_SIG_VER_BUILD | R4: 0：不上传 | S4: 模块统计信息 | U4: 寄存器类型=0x04；寄存器数量=1；转发说明=平台软件构建版本 3x
A5: 监控系统 | B5: 平台软件补丁版本 | H5: 1 | I5: U16 | J5: RO | K5: 2 | L5: 0 | M5: NULL | N5: 平台信息 | O5: 2817 | P5: COMM_SIGID_VER_HOTFIX | Q5: LOCAL_SIG_VER_HOTFIX | R5: 0：不上传 | S5: 模块统计信息 | U5: 寄存器类型=0x04；寄存器数量=1；转发说明=平台软件补丁版本 3x
A6: 通讯设备 | B6: 平台软件标签版本 | H6: 1 | I6: U16 | K6: 2 | L6: 0 | M6: NULL | N6: 平台信息 | P6: COMM_SIGID_VER_TAG | Q6: LOCAL_SIG_VER_TAG | R6: 0：不上传 | S6: 模块统计信息
A7: 监控系统 | B7: 设备序列号 | H7: 1 | I7: STRING | J7: RW | K7: 20 | L7: 17 | M7: link_inner_sn_value | N7: 平台信息 | O7: 31811 | P7: COMM_SIGID_DEV_SN | Q7: LOCAL_SIG_DEV_SN | R7: 0：不上传 | S7: 模块统计信息 | U7: 寄存器类型=0x03；寄存器数量=10；转发说明=本地设备序列号
A8: 通讯设备 | B8: 串口1工作模式 | D8: 2 | E8: 0 | F8: 5 | H8: 1 | I8: U32 | J8: RW | K8: 4 | L8: 17 | M8: local_equip_take_sig_effect | N8: 通讯参数 | P8: SIGID_UART_PORT1_WORKMODE | Q8: LOCAL_SIG_UART_PORT1_WORKMODE | R8: 0：不上传 | S8: 模块统计信息
A9: 监控系统 | B9: 串口1波特率 | D9: 115200 | E9: 0 | F9: 460800 | H9: 1 | I9: U32 | J9: RW | K9: 4 | L9: 17 | M9: local_equip_take_sig_effect | N9: 通讯参数 | P9: SIGID_UART_PORT1_BAUD | Q9: LOCAL_SIG_UART_PORT1_BAUD | R9: 0：不上传 | S9: 模块统计信息 | U9: 寄存器类型=0x03；寄存器数量=2；转发说明=串口1波特率(DCIM)
A10: 监控系统 | B10: 串口1奇偶校验 | D10: E_USART_PARITY_NO | E10: E_USART_PARITY_NO | F10: E_USART_PARITY_EVEN | H10: 1 | I10: U32 | J10: RW | K10: 4 | L10: 17 | M10: local_equip_take_sig_effect | N10: 通讯参数 | P10: SIGID_UART_PORT1_PARITY | Q10: LOCAL_SIG_UART_PORT1_PARITY | R10: 0：不上传 | S10: 模块统计信息 | U10: 寄存器类型=0x03；寄存器数量=2；转发说明=串口1奇偶校验(DCIM)
A11: 监控系统 | B11: 串口1停止位 | D11: E_USART_STOP_BIT1 | E11: E_USART_STOP_BIT1 | F11: E_USART_STOP_BIT2 | H11: 1 | I11: U32 | J11: RW | K11: 4 | L11: 17 | M11: local_equip_take_sig_effect | N11: 通讯参数 | P11: SIGID_UART_PORT1_STOP_BITS | Q11: LOCAL_SIG_UART_PORT1_STOP_BITS | R11: 0：不上传 | S11: 模块统计信息 | U11: 寄存器类型=0x03；寄存器数量=2；转发说明=串口1停止位(DCIM)
A12: 监控系统 | B12: 串口2工作模式 | H12: 1 | I12: U32 | K12: 4 | L12: 17 | M12: local_equip_take_sig_effect | N12: 通讯参数 | P12: SIGID_UART_PORT2_WORKMODE | Q12: LOCAL_SIG_UART_PORT2_WORKMODE | R12: 0：不上传 | S12: 模块统计信息
A13: 监控系统 | B13: 串口2波特率 | H13: 1 | I13: U32 | J13: RW | K13: 4 | L13: 17 | M13: local_equip_take_sig_effect | N13: 通讯参数 | P13: SIGID_UART_PORT2_BAUD | Q13: LOCAL_SIG_UART_PORT2_BAUD | R13: 0：不上传 | S13: 模块统计信息 | U13: 寄存器类型=0x03；寄存器数量=2；转发说明=串口2波特率(ICONFIG)
A14: 监控系统 | B14: 串口2奇偶校验 | H14: 1 | I14: U32 | J14: RW | K14: 4 | L14: 17 | M14: local_equip_take_sig_effect | N14: 通讯参数 | P14: SIGID_UART_PORT2_PARITY | Q14: LOCAL_SIG_UART_PORT2_PARITY | R14: 0：不上传 | S14: 模块统计信息 | U14: 寄存器类型=0x03；寄存器数量=2；转发说明=串口2奇偶校验(ICONFIG)
A15: 监控系统 | B15: 串口2停止位 | H15: 1 | I15: U32 | J15: RW | K15: 4 | L15: 17 | M15: local_equip_take_sig_effect | N15: 通讯参数 | P15: SIGID_UART_PORT2_STOP_BITS | Q15: LOCAL_SIG_UART_PORT2_STOP_BITS | R15: 0：不上传 | S15: 模块统计信息 | U15: 寄存器类型=0x03；寄存器数量=2；转发说明=串口2停止位(ICONFIG)
A16: 监控系统 | B16: 串口3工作模式 | H16: 1 | I16: U32 | K16: 4 | L16: 17 | M16: local_equip_take_sig_effect | N16: 通讯参数 | P16: SIGID_UART_PORT3_WORKMODE | Q16: LOCAL_SIG_UART_PORT3_WORKMODE | R16: 0：不上传 | S16: 模块统计信息
A17: 监控系统 | B17: 串口3波特率 | H17: 1 | I17: U32 | J17: RW | K17: 4 | L17: 17 | M17: local_equip_take_sig_effect | N17: 通讯参数 | P17: SIGID_UART_PORT3_BAUD | Q17: LOCAL_SIG_UART_PORT3_BAUD | R17: 0：不上传 | S17: 模块统计信息 | U17: 寄存器类型=0x03；寄存器数量=2；转发说明=串口3波特率(HMI)
A18: 监控系统 | B18: 串口3奇偶校验 | H18: 1 | I18: U32 | J18: RW | K18: 4 | L18: 17 | M18: local_equip_take_sig_effect | N18: 通讯参数 | P18: SIGID_UART_PORT3_PARITY | Q18: LOCAL_SIG_UART_PORT3_PARITY | R18: 0：不上传 | S18: 模块统计信息 | U18: 寄存器类型=0x03；寄存器数量=2；转发说明=串口3奇偶校验(HMI)
A19: 监控系统 | B19: 串口3停止位 | H19: 1 | I19: U32 | J19: RW | K19: 4 | L19: 17 | M19: local_equip_take_sig_effect | N19: 通讯参数 | P19: SIGID_UART_PORT3_STOP_BITS | Q19: LOCAL_SIG_UART_PORT3_STOP_BITS | R19: 0：不上传 | S19: 模块统计信息 | U19: 寄存器类型=0x03；寄存器数量=2；转发说明=串口3停止位(HMI)
A20: 监控系统 | B20: 串口4工作模式 | H20: 1 | I20: U32 | K20: 4 | L20: 17 | M20: local_equip_take_sig_effect | N20: 通讯参数 | P20: SIGID_UART_PORT4_WORKMODE | Q20: LOCAL_SIG_UART_PORT4_WORKMODE | R20: 0：不上传 | S20: 模块统计信息
A21: 监控系统 | B21: 串口4波特率 | H21: 1 | I21: U32 | K21: 4 | L21: 17 | M21: local_equip_take_sig_effect | N21: 通讯参数 | P21: SIGID_UART_PORT4_BAUD | Q21: LOCAL_SIG_UART_PORT4_BAUD | R21: 0：不上传 | S21: 模块统计信息
A22: 监控系统 | B22: 串口4奇偶校验 | H22: 1 | I22: U32 | K22: 4 | L22: 17 | M22: local_equip_take_sig_effect | N22: 通讯参数 | P22: SIGID_UART_PORT4_PARITY | Q22: LOCAL_SIG_UART_PORT4_PARITY | R22: 0：不上传 | S22: 模块统计信息
A23: 监控系统 | B23: 串口4停止位 | H23: 1 | I23: U32 | K23: 4 | L23: 17 | M23: local_equip_take_sig_effect | N23: 通讯参数 | P23: SIGID_UART_PORT4_STOP_BITS | Q23: LOCAL_SIG_UART_PORT4_STOP_BITS | R23: 0：不上传 | S23: 模块统计信息
A24: 监控系统 | B24: 串口5工作模式 | H24: 1 | I24: U32 | K24: 4 | L24: 17 | M24: local_equip_take_sig_effect | N24: 通讯参数 | P24: SIGID_UART_PORT5_WORKMODE | Q24: LOCAL_SIG_UART_PORT5_WORKMODE | R24: 0：不上传 | S24: 模块统计信息
A25: 监控系统 | B25: 串口5波特率 | H25: 1 | I25: U32 | K25: 4 | L25: 17 | M25: local_equip_take_sig_effect | N25: 通讯参数 | P25: SIGID_UART_PORT5_BAUD | Q25: LOCAL_SIG_UART_PORT5_BAUD | R25: 0：不上传 | S25: 模块统计信息
A26: 监控系统 | B26: 串口5奇偶校验 | H26: 1 | I26: U32 | K26: 4 | L26: 17 | M26: local_equip_take_sig_effect | N26: 通讯参数 | P26: SIGID_UART_PORT5_PARITY | Q26: LOCAL_SIG_UART_PORT5_PARITY | R26: 0：不上传 | S26: 模块统计信息
A27: 监控系统 | B27: 串口5停止位 | H27: 1 | I27: U32 | K27: 4 | L27: 17 | M27: local_equip_take_sig_effect | N27: 通讯参数 | P27: SIGID_UART_PORT5_STOP_BITS | Q27: LOCAL_SIG_UART_PORT5_STOP_BITS | R27: 0：不上传 | S27: 模块统计信息
A28: 监控系统 | B28: 串口6工作模式 | H28: 1 | I28: U32 | K28: 4 | L28: 17 | M28: local_equip_take_sig_effect | N28: 通讯参数 | P28: SIGID_UART_PORT6_WORKMODE | Q28: LOCAL_SIG_UART_PORT6_WORKMODE | R28: 0：不上传 | S28: 模块统计信息
A29: 监控系统 | B29: 串口6波特率 | H29: 1 | I29: U32 | K29: 4 | L29: 17 | M29: local_equip_take_sig_effect | N29: 通讯参数 | P29: SIGID_UART_PORT6_BAUD | Q29: LOCAL_SIG_UART_PORT6_BAUD | R29: 0：不上传 | S29: 模块统计信息
A30: 监控系统 | B30: 串口6奇偶校验 | H30: 1 | I30: U32 | K30: 4 | L30: 17 | M30: local_equip_take_sig_effect | N30: 通讯参数 | P30: SIGID_UART_PORT6_PARITY | Q30: LOCAL_SIG_UART_PORT6_PARITY | R30: 0：不上传 | S30: 模块统计信息
A31: 监控系统 | B31: 串口6停止位 | H31: 1 | I31: U32 | K31: 4 | L31: 17 | M31: local_equip_take_sig_effect | N31: 通讯参数 | P31: SIGID_UART_PORT6_STOP_BITS | Q31: LOCAL_SIG_UART_PORT6_STOP_BITS | R31: 0：不上传 | S31: 模块统计信息
... A73: 监控系统 | B73: CAN口2通道3范围 | H73: 1 | I73: U32 | K73: 4 | L73: 17 | M73: local_equip_take_sig_effect | N73: 通讯参数 | P73: SIGID_CAN_PORT2_CHANNEL3_RANGE | Q73: LOCAL_SIG_CAN_PORT2_CHANNEL3_RANGE | R73: 0：不上传 | S73: 模块统计信息
A74: 监控系统 | B74: modbustcp server使能1 | H74: 1 | I74: U16 | K74: 2 | L74: 17 | M74: MPP_NULL_PTR | N74: 通讯参数 | P74: SIGID_CMM_MBTCP_SERVER_FLAG1 | Q74: LOCAL_SIG_CMM_MBTCP_SERVER_FLAG1 | R74: 0：不上传 | S74: 模块统计信息 | U74: 数据定义推断来源=pub_sig_def.h注释
A75: 监控系统 | B75: modbustcp server监听端口1 | H75: 1 | I75: U16 | K75: 2 | L75: 17 | M75: MPP_NULL_PTR | N75: 通讯参数 | P75: SIGID_CMM_MBTCP_SERVER_PORT1 | Q75: LOCAL_SIG_CMM_MBTCP_SERVER_PORT1 | R75: 0：不上传 | S75: 模块统计信息 | U75: 数据定义推断来源=pub_sig_def.h注释
A76: 监控系统 | B76: 以太网DHCP使能开关 | H76: 1 | I76: U16 | J76: RW | K76: 2 | L76: 17 | M76: eth_sig_effect | N76: 通讯参数 | P76: SIGID_ETH_DHCP_ENABLE | Q76: LOCAL_SIG_ETH_DHCP_ENABLE | R76: 0：不上传 | S76: 模块统计信息 | U76: 数据定义推断来源=pub_sig_def.h注释；寄存器类型=0x03；寄存器数量=1；转发说明=DHCP使能
A77: 监控系统 | B77: 以太网IP | D77: 12.12.12.12 | H77: 1 | I77: STRING | J77: RW | K77: 16 | L77: (FLAG_PERSISTENCE |FLAG_PERSISTENCE_SYNC | FLAG_READ_CALLBACK) | M77: eth_sig_effect | N77: 通讯参数 | P77: SIGID_ETH_IP | Q77: LOCAL_SIG_ETH_IP | R77: 0：不上传 | S77: 模块统计信息 | U77: 数据定义推断来源=pub_sig_def.h注释；寄存器类型=0x03；寄存器数量=8；转发说明=IP地址
A78: 监控系统 | B78: 以太网子网掩码 | D78: 255.0.0.0 | H78: 1 | I78: STRING | J78: RW | K78: 16 | L78: (FLAG_PERSISTENCE |FLAG_PERSISTENCE_SYNC | FLAG_READ_CALLBACK) | M78: eth_sig_effect | N78: 通讯参数 | P78: SIGID_ETH_MASK | Q78: LOCAL_SIG_ETH_MASK | R78: 0：不上传 | S78: 模块统计信息 | U78: 数据定义推断来源=pub_sig_def.h注释；寄存器类型=0x03；寄存器数量=8；转发说明=子掩码
A79: 监控系统 | B79: 以太网网关 | D79: 12.12.12.1 | H79: 1 | I79: STRING | J79: RW | K79: 16 | L79: (FLAG_PERSISTENCE |FLAG_PERSISTENCE_SYNC | FLAG_READ_CALLBACK) | M79: eth_sig_effect | N79: 通讯参数 | P79: SIGID_ETH_GATEWAY | Q79: LOCAL_SIG_ETH_GATEWAY | R79: 0：不上传 | S79: 模块统计信息 | U79: 数据定义推断来源=pub_sig_def.h注释；寄存器类型=0x03；寄存器数量=8；转发说明=网关
A80: 监控系统 | B80: 以太网DNS1 | D80: 1.2.4.8 | H80: 1 | I80: STRING | J80: RW | K80: 16 | L80: (FLAG_PERSISTENCE |FLAG_PERSISTENCE_SYNC | FLAG_READ_CALLBACK) | M80: eth_sig_effect | N80: 通讯参数 | P80: SIGID_ETH_DNS1 | Q80: LOCAL_SIG_ETH_DNS1 | R80: 0：不上传 | S80: 模块统计信息 | U80: 数据定义推断来源=pub_sig_def.h注释；寄存器类型=0x03；寄存器数量=8；转发说明=DSN1
A81: 监控系统 | B81: 以太网DNS2 | D81: 8.8.8.8 | H81: 1 | I81: STRING | J81: RW | K81: 16 | L81: (FLAG_PERSISTENCE |FLAG_PERSISTENCE_SYNC | FLAG_READ_CALLBACK) | M81: eth_sig_effect | N81: 通讯参数 | P81: SIGID_ETH_DNS2 | Q81: LOCAL_SIG_ETH_DNS2 | R81: 0：不上传 | S81: 模块统计信息 | U81: 数据定义推断来源=pub_sig_def.h注释；寄存器类型=0x03；寄存器数量=8；转发说明=DSN2
...

Sheet CSU-UPM采集数据
A1: 数据来源 | B1: 数据定义 | C1: ENMU | D1: 数据类型 | E1: 离散值逻辑 | F1: 数据 长度 | G1: 默认值 | H1: 数据上限 | I1: 数据下限 | J1: 单位 | K1: 读写 权限 | L1: 精度 | M1: 数据上传 等级 | N1: UPP模型 名称 | O1: UPP地址 | P1: UPP偏移 | Q1: arm 配置参数 | R1: UPP 轮询间隔 | S1: 设置 优先级 | T1: 轮询 优先级 | U1: 回调函数 | V1: signID | W1: modbus 地址 | X1: 备注
A2: UPM | B2: 模块负载电压 | C2: UPM_SIG_LOAD_VOL | D2: U16 | F2: 2 | J2: V | K2: RO | L2: 0.1 | M2: 3：CSU进行轮询 | N2: UPM上报信息 | O2: 131 | P2: 6 | Q2: 0 | R2: 1 | S2: 0 | T2: 0 | U2: NULL | V2: 2001
A3: UPM | B3: 模块负载电流 | C3: UPM_SIG_LOAD_CUR | D3: U16 | F3: 2 | J3: A | K3: RO | L3: 0.1 | M3: 3：CSU进行轮询 | N3: UPM上报信息 | O3: 131 | P3: 8 | Q3: 0 | R3: 1 | S3: 0 | T3: 0 | U3: NULL | V3: 2002
A4: UPM | B4: 电池电压 | C4: UPM_SIG_BAT_VOL | D4: U16 | F4: 2 | J4: V | K4: RO | L4: 0.1 | M4: 3：CSU进行轮询 | N4: UPM上报信息 | O4: 131 | P4: 10 | Q4: 0 | R4: 1 | S4: 0 | T4: 0 | U4: NULL | V4: 2003
A5: UPM | B5: 电池电流 | C5: UPM_SIG_BAT_CUR | D5: U16 | F5: 2 | J5: A | K5: RO | L5: 0.1 | M5: 3：CSU进行轮询 | N5: UPM上报信息 | O5: 131 | P5: 12 | Q5: 0 | R5: 1 | S5: 0 | T5: 0 | U5: NULL | V5: 2004
A6: UPM | B6: 模块交流线电压Uab | C6: UPM_SIG_UAB_VOL | D6: U16 | F6: 2 | J6: V | K6: RO | L6: 0.1 | M6: 3：CSU进行轮询 | N6: UPM上报信息 | O6: 131 | P6: 14 | Q6: 0 | R6: 1 | S6: 0 | T6: 0 | U6: NULL | V6: 2005
A7: UPM | B7: 模块交流线电压Ubc | C7: UPM_SIG_UBC_VOL | D7: U16 | F7: 2 | J7: V | K7: RO | L7: 0.1 | M7: 3：CSU进行轮询 | N7: UPM上报信息 | O7: 131 | P7: 16 | Q7: 0 | R7: 1 | S7: 0 | T7: 0 | U7: NULL | V7: 2006
A8: UPM | B8: 模块交流线电压Uca | C8: UPM_SIG_UCA_VOL | D8: U16 | F8: 2 | J8: V | K8: RO | L8: 0.1 | M8: 3：CSU进行轮询 | N8: UPM上报信息 | O8: 131 | P8: 18 | Q8: 0 | R8: 1 | S8: 0 | T8: 0 | U8: NULL | V8: 2007
A9: UPM | B9: 交流频率 | C9: UPM_SIG_AC_FREQ | D9: U16 | F9: 2 | J9: Hz | K9: RO | L9: 0.1 | M9: 3：CSU进行轮询 | N9: UPM上报信息 | O9: 131 | P9: 20 | Q9: 0 | R9: 1 | S9: 0 | T9: 0 | U9: NULL | V9: 2008
A10: UPM | B10: 模块温度 | C10: UPM_SIG_TEMP | D10: U16 | F10: 2 | J10: ℃ | K10: RO | L10: 0.1 | M10: 3：CSU进行轮询 | N10: UPM上报信息 | O10: 131 | P10: 22 | Q10: 0 | R10: 1 | S10: 0 | T10: 0 | U10: NULL | V10: 2009
A11: UPM | B11: 子板供电方式 | C11: UPM_SIG_POWER_MODE_STATE | D11: U16 | E11: bit0 - cell1 0-AC 1-DC bit1 - cell2 0-AC 1-DC bit2 - cell3 0-AC 1-DC bit3 - cell4 0-AC 1-DC bit4 - cell50-AC 1-DC bit5 - cell6 0-AC 1-DC bit6 - cell7 0-AC 1-DC bit7 - cell8 0-AC 1-DC | F11: 2 | K11: RO | M11: 3：CSU进行轮询 | N11: UPM状态信息 | O11: 132 | P11: 6 | Q11: 0 | R11: 1 | S11: 0 | T11: 0 | U11: NULL | V11: 2501
A12: UPM | B12: 子板开关机状态 | C12: UPM_SIG_POWER_ OFF_STATE | D12: U16 | E12: bit0- cell1 0-关机 1-开机 bit1 - cell2 0-关机 1-开机 bit2- cell3 0-关机 1-开机 bit3 - cell4 0-关机 1-开机 bit4- cell5 0-关机 1-开机 bit5 - cell6 0-关机 1-开机 bit6- cell7 0-关机 1-开机 bit7 - cell8 0-关机 1-开机 | F12: 2 | K12: RO | M12: 3：CSU进行轮询 | N12: UPM状态信息 | O12: 132 | P12: 8 | Q12: 0 | R12: 1 | S12: 0 | T12: 0 | U12: NULL | V12: 2502
A13: UPM | B13: 子板休眠状态 | C13: UPM_SIG_SLEEP_STATE | D13: U16 | E13: bit0- cell1 0-工作 bit1 - cell2 0-工作 1-休眠 bit2- cell3 0-工作 1-休眠 bit3 - cell4 0-工作 1-休眠 bit4- cell5 0-工作 1-休眠 bit5 - cell6 0-工作 1-休眠 bit6- cell7 0-工作 1-休眠 bit7 - cell8 0-工作 1-休眠 | F13: 2 | K13: RO | M13: 3：CSU进行轮询 | N13: UPM状态信息 | O13: 132 | P13: 10 | Q13: 0 | R13: 1 | S13: 0 | T13: 0 | U13: NULL | V13: 2503
A14: UPM | B14: 模块故障1模块故障1 | C14: UPM_SIG_FAULT_STATE1 | D14: U32 | E14: bit0 - 模块故障 bit1 -模块均流故障 bit2 -模块风扇故障 bit3 -模块过温 bit4-限流限功率 | F14: 4 | K14: RO | M14: 3：CSU进行轮询 | N14: UPM状态信息 | O14: 132 | P14: 12 | Q14: 0 | R14: 1 | S14: 0 | T14: 0 | U14: NULL | V14: 2504 | X14: 或关系
A15: UPM | B15: 模块交流故障 | C15: UPM_SIG_AC_FAULT_STATE | D15: U16 | E15: bit0 -模块交流线电压Uab高 bit1 -模块交流线电压Ubc高 bit2 -模块交流线电压Uca高 bit3 -模块交流线电压Uab低 bit4 -模块交流线电压Ubc低 bit5 -模块交流线电压Uca低 bit6 -模块交流中断 bit7 -模块交流频率高 bit8 -模块交流频率低 | F15: 2 | K15: RO | M15: 3：CSU进行轮询 | N15: UPM状态信息 | O15: 132 | P15: 16 | Q15: 0 | R15: 1 | S15: 0 | T15: 0 | U15: NULL | V15: 2505 | X15: 交流信息由UPM判断故障和非故障
A16: UPM | B16: 子板故障状态 | C16: UPM_SIG_SUB_BOARD_FAULT_STATE | D16: U16 | E16: bit0- cell1 0-正常 1-故障 bit1 - cell2 0-正常 1-故障 bit2- cell3 0-正常 1-故障 bit3 - cell4 0-正常 1-故障 bit4- cell5 0-正常 1-故障 bit5 - cell6 0-正常 1-故障 bit6- cell7 0-正常 1-故障 bit7 - cell8 0-正常 1-故障 | F16: 2 | K16: RO | M16: 3：CSU进行轮询 | N16: UPM状态信息 | O16: 132 | P16: 18 | Q16: 0 | R16: 1 | S16: 0 | T16: 0 | U16: NULL | V16: 2506
A17: UPM | B17: 负载输出电压设置 | C17: UPM_SIG_LOAD_VOL_SET | D17: U16 | F17: 2 | G17: 270 | J17: V | K17: RW | L17: 0.1 | M17: 3：CSU进行轮询 | N17: UPM设置参数 | O17: 133 | P17: 6 | Q17: 0 | R17: 30 | S17: 0 | T17: 0 | U17: NULL | V17: 3001
A18: UPM | B18: 负载输出限流值 | C18: UPM_SIG_LOAD_CUR_SET | D18: U16 | F18: 2 | G18: 100 | J18: A | K18: RW | L18: 0.1 | M18: 3：CSU进行轮询 | N18: UPM设置参数 | O18: 133 | P18: 8 | Q18: 0 | R18: 30 | S18: 0 | T18: 0 | U18: NULL | V18: 3002
A19: UPM | B19: 负载输出电压缺省值 | C19: UPM_SIG_LOAD_DEFAULT_VOL | D19: U16 | F19: 2 | G19: 270 | J19: V | K19: RW | L19: 0.1 | M19: 3：CSU进行轮询 | N19: UPM设置参数 | O19: 133 | P19: 10 | Q19: 0 | R19: 30 | S19: 0 | T19: 0 | U19: NULL | V19: 3003
A20: UPM | B20: 电池电压设置 | C20: UPM_SIG_BAT_VOL_SET | D20: U16 | F20: 2 | G20: 270 | J20: V | K20: RW | L20: 0.1 | M20: 3：CSU进行轮询 | N20: UPM设置参数 | O20: 133 | P20: 12 | Q20: 0 | R20: 30 | S20: 0 | T20: 0 | U20: NULL | V20: 3004 | X20: 不做广播
A21: UPM | B21: 电池限流设置 | C21: UPM_SIG_BAT_CUR_SET | D21: U16 | F21: 2 | G21: 10 | J21: A | K21: RW | L21: 0.1 | M21: 3：CSU进行轮询 | N21: UPM设置参数 | O21: 133 | P21: 14 | Q21: 0 | R21: 30 | S21: 0 | T21: 0 | U21: NULL | V21: 3005 | X21: 不做广播
A22: UPM | B22: 电池输出点电压缺省值 | C22: UPM_SIG_BAT_DEFAULT_VOL | D22: U16 | F22: 2 | G22: 270 | J22: V | K22: RW | L22: 0.1 | M22: 3：CSU进行轮询 | N22: UPM设置参数 | O22: 133 | P22: 16 | Q22: 0 | R22: 30 | S22: 0 | T22: 0 | U22: NULL | V22: 3006
